Workbook
Name AA: #REF!
Name AA: #REF!
Name AA: #REF!
Name AA: #REF!
Name AAA: #REF!
Name AAA: #REF!
Name AAA: #REF!
Name AAA: #REF!
Name Fase_07: [2]Medição!#REF!
Name Fase_07: [2]Medição!#REF!
Name Fase_07: [2]Medição!#REF!
Name Fase_07: [2]Medição!#REF!
Name H: #REF!
Name H: #REF!
Name H: #REF!
Name H: #REF!
Name I: #REF!
Name I: #REF!
Name I: #REF!
Name I: #REF!
Name p: #REF!
Name p: #REF!
Name p: #REF!
Name p: #REF!
Name ProteçãoAmbiental: '[2]Medição Completa'!#REF!
Name ProteçãoAmbiental: '[2]Medição Completa'!#REF!
Name ProteçãoAmbiental: '[2]Medição Completa'!#REF!
Name ProteçãoAmbiental: '[2]Medição Completa'!#REF!

Sheet FR-IMOB-55_Rev00
A1: Título: Ensaio de Compactação de Solo Completo
A3: Tipo de Documento: Formulário | H3: Codificação: FR-IMOB-55
A4: Data de Vigência: 16/02/2026 | H4: Versão: 00
A5: Fase: Vigente | H5: Nível: Operacional
A7: COMPACTAÇÃO COMPLETO | K7: Registro | N7: ITEM | AK7: =(N8-1)*7+4 -> 4 | AL7: TRUE | AM7: TRUE | AN7: TRUE | AO7: TRUE | AP7: TRUE | AQ7: TRUE | AS7: TRUE | AT7: =IF(AS7=FALSE,AS8=FALSE) -> FALSE | AU7: FALSE | BD7: =MIN($AL13:$AQ13) -> 0.023450524 | BE7: =BD7 -> 0.023450524 | BF7: =BE7+$BC$8 -> 0.024062061 | BG7: =BF7+$BC$8 -> 0.024673598 | BH7: =BG7+$BC$8 -> 0.025285135 | BI7: =BH7+$BC$8 -> 0.025896672 | BJ7: =BI7+$BC$8 -> 0.026508208 | BK7: =BJ7+$BC$8 -> 0.027119745 | BL7: =BK7+$BC$8 -> 0.027731282 | BM7: =BL7+$BC$8 -> 0.028342819 | ... EZ7: =EY7+$BC$8 -> 0.083992668
L8: =IF(OR($N$8="",$N$8=0),"",IF(INDIRECT(ADDRESS(($AK8),COLUMN()-7,,,"Digitar Dados dos Ensaios"))<>"",INDIRECT(ADDRESS(($AK8),COLUMN()-7,,,"Digitar Dados dos Ensaios")),"")) -> 1 | N8: 1 | AK8: =AK7+2 -> 6 | AL8: FALSE | AM8: TRUE | AN8: TRUE | AO8: TRUE | AP8: TRUE | AQ8: TRUE | AS8: FALSE | AU8: TRUE | BC8: =($BD$8-$BD$7)/99 -> 0.0006115368 | BD8: =MAX($AL13:$AQ13) -> 0.083992668 | BE8: =$AT$19*BE7^2+$AV$19*BE7+$AX$19 -> 1859.4322 | BF8: =$AT$19*BF7^2+$AV$19*BF7+$AX$19 -> 1872.1425 | BG8: =$AT$19*BG7^2+$AV$19*BG7+$AX$19 -> 1884.6243 | BH8: =$AT$19*BH7^2+$AV$19*BH7+$AX$19 -> 1896.8775 | BI8: =$AT$19*BI7^2+$AV$19*BI7+$AX$19 -> 1908.9022 | BJ8: =$AT$19*BJ7^2+$AV$19*BJ7+$AX$19 -> 1920.6983 | BK8: =$AT$19*BK7^2+$AV$19*BK7+$AX$19 -> 1932.2659 | BL8: =$AT$19*BL7^2+$AV$19*BL7+$AX$19 -> 1943.6049 | ... EZ8: =$AT$19*EZ7^2+$AV$19*EZ7+$AX$19 -> 2009.0649
K9: Data
AL10: TRUE | AM10: TRUE | AN10: TRUE | AO10: TRUE | AP10: TRUE | AQ10: TRUE | BE10: =($AU$99*BE7^2+$AW$99*BE7+$AY$99) -> #REF! | BF10: =($AU$99*BF7^2+$AW$99*BF7+$AY$99) -> #REF! | BG10: =($AU$99*BG7^2+$AW$99*BG7+$AY$99) -> #REF! | BH10: =($AU$99*BH7^2+$AW$99*BH7+$AY$99) -> #REF! | BI10: =($AU$99*BI7^2+$AW$99*BI7+$AY$99) -> #REF! | BJ10: =($AU$99*BJ7^2+$AW$99*BJ7+$AY$99) -> #REF! | BK10: =($AU$99*BK7^2+$AW$99*BK7+$AY$99) -> #REF! | BL10: =($AU$99*BL7^2+$AW$99*BL7+$AY$99) -> #REF! | ... EZ10: =($AU$99*EZ7^2+$AW$99*EZ7+$AY$99) -> #REF!
A11: Documento de Referência | AK11: =AK7+3 -> 7 | BE11: =$AU$108*BE7^2+$AW$108*BE7+$AY$108 -> #REF! | BF11: =$AU$108*BF7^2+$AW$108*BF7+$AY$108 -> #REF! | BG11: =$AU$108*BG7^2+$AW$108*BG7+$AY$108 -> #REF! | BH11: =$AU$108*BH7^2+$AW$108*BH7+$AY$108 -> #REF! | BI11: =$AU$108*BI7^2+$AW$108*BI7+$AY$108 -> #REF! | BJ11: =$AU$108*BJ7^2+$AW$108*BJ7+$AY$108 -> #REF! | BK11: =$AU$108*BK7^2+$AW$108*BK7+$AY$108 -> #REF! | BL11: =$AU$108*BL7^2+$AW$108*BL7+$AY$108 -> #REF! | ... EZ11: =$AU$108*EZ7^2+$AW$108*EZ7+$AY$108 -> #REF!
A12: DNIT 164 - ME - Solos - Compactação utilizando amostras não trabalhadas
A13: Estaca : | B13: =IF(OR($N$8="",$N$8=0),"",IF(INDIRECT(ADDRESS(($AK13),COLUMN()+1,,,"Digitar Dados dos Ensaios"))<>"",INDIRECT(ADDRESS(($AK13),COLUMN()+1,,,"Digitar Dados dos Ensaios")),"")) | D13: Posição | E13: =IF(OR($N$8="",$N$8=0),"",IF(INDIRECT(ADDRESS(($AK13)+1,COLUMN()-2,,,"Digitar Dados dos Ensaios"))<>"",INDIRECT(ADDRESS(($AK13)+1,COLUMN()-2,,,"Digitar Dados dos Ensaios")),"")) -> - | F13: =IF(OR($N$8="",$N$8=0),"",IF(INDIRECT(ADDRESS(($AK13),COLUMN(),,,"Digitar Dados dos Ensaios"))<>"",INDIRECT(ADDRESS(($AK13),COLUMN(),,,"Digitar Dados dos Ensaios")),"")) -> Marque com X se a Compactação é | G13: Camada : | H13: =IF(OR($N$8="",$N$8=0),"",IF(INDIRECT(ADDRESS(($AK15),COLUMN()-5,,,"Digitar Dados dos Ensaios"))<>"",INDIRECT(ADDRESS(($AK15),COLUMN()-5,,,"Digitar Dados dos Ensaios")),"")) -> AVALIAR | I13: =IF(OR($N$8="",$N$8=0),"",IF(INDIRECT(ADDRESS(($AK13),COLUMN()-2,,,"Digitar Dados dos Ensaios"))<>"",INDIRECT(ADDRESS(($AK13),COLUMN()-2,,,"Digitar Dados dos Ensaios")),"")) -> Simples | J13: =IF(OR($N$8="",$N$8=0),"",IF(INDIRECT(ADDRESS(($AK13),COLUMN()-2,,,"Digitar Dados dos Ensaios"))<>"",INDIRECT(ADDRESS(($AK13),COLUMN()-2,,,"Digitar Dados dos Ensaios")),"")) | K13: =IF(OR($N$8="",$N$8=0),"",IF(INDIRECT(ADDRESS(($AK13),COLUMN()-2,,,"Digitar Dados dos Ensaios"))<>"",INDIRECT(ADDRESS(($AK13),COLUMN()-2,,,"Digitar Dados dos Ensaios")),"")) -> Nº da Cápsula | L13: =IF(OR($N$8="",$N$8=0),"",IF(INDIRECT(ADDRESS(($AK13),COLUMN()-2,,,"Digitar Dados dos Ensaios"))<>"",INDIRECT(ADDRESS(($AK13),COLUMN()-2,,,"Digitar Dados dos Ensaios")),"")) | AK13: =AK7+2 -> 6 | AL13: =IF(AL14="","",IF($AS$7=TRUE,D26,IF($AS8=TRUE,D25,""))) -> 0.023450524 | AM13: =IF(AM14="","",IF($AS$7=TRUE,E26,IF($AS8=TRUE,E25,""))) -> 0.03858606 | AN13: =IF(AN14="","",IF($AS$7=TRUE,F26,IF($AS8=TRUE,F25,""))) -> 0.053721596 | AO13: =IF(AO14="","",IF($AS$7=TRUE,G26,IF($AS8=TRUE,G25,""))) -> 0.068857132 | AP13: =IF(AP14="","",IF($AS$7=TRUE,H26,IF($AS8=TRUE,H25,""))) -> 0.083992668 | AQ13: =IF(AQ14="","",IF($AS$7=TRUE,I26,IF($AS8=TRUE,I25,""))) | AR13: =AVERAGE(AL13:AQ13) -> 0.053721596 | AS13: =IF(ISNUMBER(AL16),AL16^2,"") -> 0.00091633779 | AT13: =IF(ISNUMBER(AM16),AM16^2,"") -> 0.00022908445 | AU13: =IF(ISNUMBER(AN16),AN16^2,"") -> 0 | AV13: =IF(ISNUMBER(AO16),AO16^2,"") -> 0.00022908445 | AW13: =IF(ISNUMBER(AP16),AP16^2,"") -> 0.00091633779 | AX13: =IF(ISNUMBER(AQ16),AQ16^2,"") | AY13: =SUM(AS13:AX13) -> 0.0022908445 | AZ13: x= | BA13: =-AV19/(2*AT19) -> 0.057765822
A14: Próctor: | B14: =IF(OR($N$8="",$N$8=0),"",IF(INDIRECT(ADDRESS(($AK$14-1),COLUMN()+1,,,"Digitar Dados dos Ensaios"))<>"",INDIRECT(ADDRESS(($AK$14-1),COLUMN()+1,,,"Digitar Dados dos Ensaios")),"")) -> MODIFICADO | C14: =IF(OR($M$8="",$M$8=0),"",IF(INDIRECT(ADDRESS(($M$8-1)*4+4,COLUMN(),,,"Digitar Dados dos Ensaios"))<>"",INDIRECT(ADDRESS(($M$8-1)*4+4,COLUMN(),,,"Digitar Dados dos Ensaios")),"")) | D14: Golpes: | E14: =IF(OR($N$8="",$N$8=0),"",IF(INDIRECT(ADDRESS(($AK14),COLUMN()-2,,,"Digitar Dados dos Ensaios"))<>"",INDIRECT(ADDRESS(($AK14),COLUMN()-2,,,"Digitar Dados dos Ensaios")),"")) -> 55 | F14: =IF(OR($N$8="",$N$8=0),"",IF(INDIRECT(ADDRESS(($AK14),COLUMN(),,,"Digitar Dados dos Ensaios"))<>"",INDIRECT(ADDRESS(($AK14),COLUMN(),,,"Digitar Dados dos Ensaios")),"")) | G14: Rodovia: | H14: ='Digitar Dados dos Ensaios'!A1 -> BR -163 | I14: =IF(OR($N$8="",$N$8=0),"",IF(INDIRECT(ADDRESS(($AK14),COLUMN()-2,,,"Digitar Dados dos Ensaios"))<>"",INDIRECT(ADDRESS(($AK14),COLUMN()-2,,,"Digitar Dados dos Ensaios")),"")) -> Pela Higroscópica | J14: =IF(OR($N$8="",$N$8=0),"",IF(INDIRECT(ADDRESS(($AK14),COLUMN()-2,,,"Digitar Dados dos Ensaios"))<>"",INDIRECT(ADDRESS(($AK14),COLUMN()-2,,,"Digitar Dados dos Ensaios")),"")) -> X | K14: =IF(OR($N$8="",$N$8=0),"",IF(INDIRECT(ADDRESS(($AK14),COLUMN()-2,,,"Digitar Dados dos Ensaios"))<>"",INDIRECT(ADDRESS(($AK14),COLUMN()-2,,,"Digitar Dados dos Ensaios")),"")) -> Peso Bruto | L14: =IF(OR($N$8="",$N$8=0),"",IF(INDIRECT(ADDRESS(($AK14),COLUMN()-2,,,"Digitar Dados dos Ensaios"))<>"",INDIRECT(ADDRESS(($AK14),COLUMN()-2,,,"Digitar Dados dos Ensaios")),"")) -> 9575 | AK14: =AK13+5 -> 11 | AL14: =IF(AL$7=TRUE,D36,"") -> 1898.3267 | AM14: =IF(AM$7=TRUE,E36,"") -> 2018.6054 | AN14: =IF(AN$7=TRUE,F36,"") -> 2245.5883 | AO14: =IF(AO$7=TRUE,G36,"") -> 2228.107 | AP14: =IF(AP$7=TRUE,H36,"") -> 1980.6168 | AQ14: =IF(AQ$7=TRUE,I36,"") | AR14: =AVERAGE(AL14:AQ14) -> 2074.2488 | AS14: =IF(ISNUMBER(AL18),AL18^2,"") -> 7.8078426e-06 | AT14: =IF(ISNUMBER(AM18),AM18^2,"") -> 3.4421186e-06 | AU14: =IF(ISNUMBER(AN18),AN18^2,"") -> 2.0991874e-07 | AV14: =IF(ISNUMBER(AO18),AO18^2,"") -> 1.9519606e-06 | AW14: =IF(ISNUMBER(AP18),AP18^2,"") -> 1.3768474e-05 | AX14: =IF(ISNUMBER(AQ18),AQ18^2,"") | AY14: =SUM(AS14:AX14) -> 2.7180315e-05 | AZ14: y= | BA14: =AT19*BA13^2+AV19*BA13+AX19 -> 2219.2469
A15: Trecho: | B15: ='Digitar Dados dos Ensaios'!A2 -> Nova Mutum- MT | AK15: =AK7+4 -> 8 | AL15: =IF(ISNUMBER(AL13),AL13^2,"") -> 0.00054992709 | AM15: =IF(ISNUMBER(AM13),AM13^2,"") -> 0.001488884 | AN15: =IF(ISNUMBER(AN13),AN13^2,"") -> 0.0028860099 | AO15: =IF(ISNUMBER(AO13),AO13^2,"") -> 0.0047413046 | AP15: =IF(ISNUMBER(AP13),AP13^2,"") -> 0.0070547683 | AQ15: =IF(ISNUMBER(AQ13),AQ13^2,"") | AR15: =AVERAGE(AL15:AQ15) -> 0.0033441788 | AS15: =IF(ISERROR(AL17*AL17),"",AL16*AL17) -> 5.3253522 | AT15: =IF(ISERROR(AM17*AM17),"",AM16*AM17) -> 0.84219282 | AU15: =IF(ISERROR(AN17*AN17),"",AN16*AN17) -> 0 | AV15: =IF(ISERROR(AO17*AO17),"",AO16*AO17) -> 2.3287259 | AW15: =IF(ISERROR(AP17*AP17),"",AP16*AP17) -> -2.8343423 | AX15: =IF(ISERROR(AQ17*AQ17),"",AQ16*AQ17) | AY15: =SUM(AS15:AX15) -> 5.6619286
A16: Sub-Trecho: | B16: ='Digitar Dados dos Ensaios'!A3 -> 0 | AK16: =AK15+1 -> 9 | AL16: =IF(ISNUMBER(AL13),AL13-$AR13,"") -> -0.030271072 | AM16: =IF(ISNUMBER(AM13),AM13-$AR13,"") -> -0.015135536 | AN16: =IF(ISNUMBER(AN13),AN13-$AR13,"") -> 0 | AO16: =IF(ISNUMBER(AO13),AO13-$AR13,"") -> 0.015135536 | AP16: =IF(ISNUMBER(AP13),AP13-$AR13,"") -> 0.030271072 | AQ16: =IF(ISNUMBER(AQ13),AQ13-$AR13,"") | AS16: =IF(ISERROR(AL17*AL18),"",AL17*AL18) -> 0.49157078 | AT16: =IF(ISERROR(AM17*AM18),"",AM17*AM18) -> 0.10323493 | AU16: =IF(ISERROR(AN17*AN18),"",AN17*AN18) -> -0.0785024 | AV16: =IF(ISERROR(AO17*AO18),"",AO17*AO18) -> 0.21495923 | AW16: =IF(ISERROR(AP17*AP18),"",AP17*AP18) -> -0.34743007 | AX16: =IF(ISERROR(AQ17*AQ18),"",AQ17*AQ18) | AY16: =SUM(AS16:AX16) -> 0.38383246
AL17: =IF(ISNUMBER(AL14),AL14-$AR14,"") -> -175.92215 | AM17: =IF(ISNUMBER(AM14),AM14-$AR14,"") -> -55.643409 | AN17: =IF(ISNUMBER(AN14),AN14-$AR14,"") -> 171.33944 | AO17: =IF(ISNUMBER(AO14),AO14-$AR14,"") -> 153.85817 | AP17: =IF(ISNUMBER(AP14),AP14-$AR14,"") -> -93.632043 | AQ17: =IF(ISNUMBER(AQ14),AQ14-$AR14,"") | AS17: =IF(ISERROR(AL16*AL18),"",AL16*AL18) -> 8.4584994e-05 | AT17: =IF(ISERROR(AM16*AM18),"",AM16*AM18) -> 2.808088e-05 | AU17: =IF(ISERROR(AN16*AN18),"",AN16*AN18) -> 0 | AV17: =IF(ISERROR(AO16*AO18),"",AO16*AO18) -> 2.1146248e-05 | AW17: =IF(ISERROR(AP16*AP18),"",AP16*AP18) -> 0.00011232352 | AX17: =IF(ISERROR(AQ16*AQ18),"",AQ16*AQ18) | AY17: =SUM(AS17:AX17) -> 0.00024613564
A18: Item | C18: Unid. | D18: =IF(OR($N$8="",$N$8=0),"",IF(INDIRECT(ADDRESS(($AK18),COLUMN()+6,,,"Digitar Dados dos Ensaios"))<>"",INDIRECT(ADDRESS(($AK18),COLUMN()+6,,,"Digitar Dados dos Ensaios")),"")) -> 1 | E18: =IF(OR($N$8="",$N$8=0),"",IF(INDIRECT(ADDRESS(($AK18),COLUMN()+6,,,"Digitar Dados dos Ensaios"))<>"",INDIRECT(ADDRESS(($AK18),COLUMN()+6,,,"Digitar Dados dos Ensaios")),"")) -> 2 | F18: =IF(OR($N$8="",$N$8=0),"",IF(INDIRECT(ADDRESS(($AK18),COLUMN()+6,,,"Digitar Dados dos Ensaios"))<>"",INDIRECT(ADDRESS(($AK18),COLUMN()+6,,,"Digitar Dados dos Ensaios")),"")) -> 3 | G18: =IF(OR($N$8="",$N$8=0),"",IF(INDIRECT(ADDRESS(($AK18),COLUMN()+6,,,"Digitar Dados dos Ensaios"))<>"",INDIRECT(ADDRESS(($AK18),COLUMN()+6,,,"Digitar Dados dos Ensaios")),"")) -> 4 | H18: =IF(OR($N$8="",$N$8=0),"",IF(INDIRECT(ADDRESS(($AK18),COLUMN()+6,,,"Digitar Dados dos Ensaios"))<>"",INDIRECT(ADDRESS(($AK18),COLUMN()+6,,,"Digitar Dados dos Ensaios")),"")) -> 5 | I18: =IF(OR($N$8="",$N$8=0),"",IF(INDIRECT(ADDRESS(($AK18),COLUMN()+6,,,"Digitar Dados dos Ensaios"))<>"",INDIRECT(ADDRESS(($AK18),COLUMN()+6,,,"Digitar Dados dos Ensaios")),"")) | J18: =IF(OR($N$8="",$N$8=0),"",IF(INDIRECT(ADDRESS(($AK18),COLUMN()+6,,,"Digitar Dados dos Ensaios"))<>"",INDIRECT(ADDRESS(($AK18),COLUMN()+6,,,"Digitar Dados dos Ensaios")),"")) -> Umidade Higroscópica | K18: Umidade Higroscópica | AK18: =AK7+1 -> 5 | AL18: =IF(ISNUMBER(AL15),AL15-$AR15,"") -> -0.0027942517 | AM18: =IF(ISNUMBER(AM15),AM15-$AR15,"") -> -0.0018552947 | AN18: =IF(ISNUMBER(AN15),AN15-$AR15,"") -> -0.0004581689 | AO18: =IF(ISNUMBER(AO15),AO15-$AR15,"") -> 0.0013971258 | AP18: =IF(ISNUMBER(AP15),AP15-$AR15,"") -> 0.0037105895 | AQ18: =IF(ISNUMBER(AQ15),AQ15-$AR15,"")
A19: Cápsula Nº | C19: - | D19: =IF(OR($N$8="",$N$8=0),"",IF(INDIRECT(ADDRESS(($AK19),COLUMN()+6,,,"Digitar Dados dos Ensaios"))<>"",INDIRECT(ADDRESS(($AK19),COLUMN()+6,,,"Digitar Dados dos Ensaios")),"")) | E19: =IF(OR($N$8="",$N$8=0),"",IF(INDIRECT(ADDRESS(($AK19),COLUMN()+6,,,"Digitar Dados dos Ensaios"))<>"",INDIRECT(ADDRESS(($AK19),COLUMN()+6,,,"Digitar Dados dos Ensaios")),"")) | F19: =IF(OR($N$8="",$N$8=0),"",IF(INDIRECT(ADDRESS(($AK19),COLUMN()+6,,,"Digitar Dados dos Ensaios"))<>"",INDIRECT(ADDRESS(($AK19),COLUMN()+6,,,"Digitar Dados dos Ensaios")),"")) | G19: =IF(OR($N$8="",$N$8=0),"",IF(INDIRECT(ADDRESS(($AK19),COLUMN()+6,,,"Digitar Dados dos Ensaios"))<>"",INDIRECT(ADDRESS(($AK19),COLUMN()+6,,,"Digitar Dados dos Ensaios")),"")) | H19: =IF(OR($N$8="",$N$8=0),"",IF(INDIRECT(ADDRESS(($AK19),COLUMN()+6,,,"Digitar Dados dos Ensaios"))<>"",INDIRECT(ADDRESS(($AK19),COLUMN()+6,,,"Digitar Dados dos Ensaios")),"")) | I19: =IF(OR($N$8="",$N$8=0),"",IF(INDIRECT(ADDRESS(($AK19),COLUMN()+6,,,"Digitar Dados dos Ensaios"))<>"",INDIRECT(ADDRESS(($AK19),COLUMN()+6,,,"Digitar Dados dos Ensaios")),"")) | J19: =IF(OR($N$8="",$N$8=0),"",IF(INDIRECT(ADDRESS(($AK19),COLUMN()+6,,,"Digitar Dados dos Ensaios"))<>"",INDIRECT(ADDRESS(($AK19),COLUMN()+6,,,"Digitar Dados dos Ensaios")),"")) -> 10 | K19: =IF(OR($N$8="",$N$8=0),"",IF(INDIRECT(ADDRESS(($AK19),COLUMN()+5,,,"Digitar Dados dos Ensaios"))<>"",INDIRECT(ADDRESS(($AK19),COLUMN()+5,,,"Digitar Dados dos Ensaios")),"")) -> 10 | L19: =IF(OR($N$8="",$N$8=0),"",IF(INDIRECT(ADDRESS(($AK19),COLUMN()+5,,,"Digitar Dados dos Ensaios"))<>"",INDIRECT(ADDRESS(($AK19),COLUMN()+5,,,"Digitar Dados dos Ensaios")),"")) -> 21 | AK19: =AK7+2 -> 6 | AL19: =IF(OR(AL13="",AL13=0),NA(),AL13) -> 0.023450524 | AM19: =IF(OR(AM13="",AM13=0),NA(),AM13) -> 0.03858606 | AN19: =IF(OR(AN13="",AN13=0),NA(),AN13) -> 0.053721596 | AO19: =IF(OR(AO13="",AO13=0),NA(),AO13) -> 0.068857132 | AP19: =IF(OR(AP13="",AP13=0),NA(),AP13) -> 0.083992668 | AQ19: =IF(OR(AQ13="",AQ13=0),NA(),AQ13) -> #N/A | AS19: a | AT19: =(AY15*AY17-AY16*AY13)/(AY17^2-AY14*AY13) -> -305564.81 | AU19: b | AV19: =(AY16-AT19*AY14)/AY17 -> 35302.405 | AW19: c | AX19: =AR14-AV19*AR13-AT19*AR15 -> 1199.6106 | AZ19: Densidade
A20: Peso Bruto Úmido | C20: g | D20: =IF(OR($N$8="",$N$8=0),"",IF(INDIRECT(ADDRESS(($AK20),COLUMN()+6,,,"Digitar Dados dos Ensaios"))<>"",INDIRECT(ADDRESS(($AK20),COLUMN()+6,,,"Digitar Dados dos Ensaios")),"")) | E20: =IF(OR($N$8="",$N$8=0),"",IF(INDIRECT(ADDRESS(($AK20),COLUMN()+6,,,"Digitar Dados dos Ensaios"))<>"",INDIRECT(ADDRESS(($AK20),COLUMN()+6,,,"Digitar Dados dos Ensaios")),"")) | F20: =IF(OR($N$8="",$N$8=0),"",IF(INDIRECT(ADDRESS(($AK20),COLUMN()+6,,,"Digitar Dados dos Ensaios"))<>"",INDIRECT(ADDRESS(($AK20),COLUMN()+6,,,"Digitar Dados dos Ensaios")),"")) | G20: =IF(OR($N$8="",$N$8=0),"",IF(INDIRECT(ADDRESS(($AK20),COLUMN()+6,,,"Digitar Dados dos Ensaios"))<>"",INDIRECT(ADDRESS(($AK20),COLUMN()+6,,,"Digitar Dados dos Ensaios")),"")) | H20: =IF(OR($N$8="",$N$8=0),"",IF(INDIRECT(ADDRESS(($AK20),COLUMN()+6,,,"Digitar Dados dos Ensaios"))<>"",INDIRECT(ADDRESS(($AK20),COLUMN()+6,,,"Digitar Dados dos Ensaios")),"")) | I20: =IF(OR($N$8="",$N$8=0),"",IF(INDIRECT(ADDRESS(($AK20),COLUMN()+6,,,"Digitar Dados dos Ensaios"))<>"",INDIRECT(ADDRESS(($AK20),COLUMN()+6,,,"Digitar Dados dos Ensaios")),"")) | J20: =IF(OR($N$8="",$N$8=0),"",IF(INDIRECT(ADDRESS(($AK20),COLUMN()+6,,,"Digitar Dados dos Ensaios"))<>"",INDIRECT(ADDRESS(($AK20),COLUMN()+6,,,"Digitar Dados dos Ensaios")),"")) -> 186.55 | K20: =IF(OR($N$8="",$N$8=0),"",IF(INDIRECT(ADDRESS(($AK20),COLUMN()+5,,,"Digitar Dados dos Ensaios"))<>"",INDIRECT(ADDRESS(($AK20),COLUMN()+5,,,"Digitar Dados dos Ensaios")),"")) -> 186.55 | L20: =IF(OR($N$8="",$N$8=0),"",IF(INDIRECT(ADDRESS(($AK20),COLUMN()+5,,,"Digitar Dados dos Ensaios"))<>"",INDIRECT(ADDRESS(($AK20),COLUMN()+5,,,"Digitar Dados dos Ensaios")),"")) -> 201.76 | AK20: =AK19+1 -> 7 | AL20: =IF(OR(AL14="",AL14=0),NA(),AL14) -> 1898.3267 | AM20: =IF(OR(AM14="",AM14=0),NA(),AM14) -> 2018.6054 | AN20: =IF(OR(AN14="",AN14=0),NA(),AN14) -> 2245.5883 | AO20: =IF(OR(AO14="",AO14=0),NA(),AO14) -> 2228.107 | AP20: =IF(OR(AP14="",AP14=0),NA(),AP14) -> 1980.6168 | AQ20: =IF(OR(AQ14="",AQ14=0),NA(),AQ14) -> #N/A | AZ20: x | BA20: y
A21: Peso Bruto Seco | C21: g | D21: =IF(OR($N$8="",$N$8=0),"",IF(INDIRECT(ADDRESS(($AK21),COLUMN()+6,,,"Digitar Dados dos Ensaios"))<>"",INDIRECT(ADDRESS(($AK21),COLUMN()+6,,,"Digitar Dados dos Ensaios")),"")) | E21: =IF(OR($N$8="",$N$8=0),"",IF(INDIRECT(ADDRESS(($AK21),COLUMN()+6,,,"Digitar Dados dos Ensaios"))<>"",INDIRECT(ADDRESS(($AK21),COLUMN()+6,,,"Digitar Dados dos Ensaios")),"")) | F21: =IF(OR($N$8="",$N$8=0),"",IF(INDIRECT(ADDRESS(($AK21),COLUMN()+6,,,"Digitar Dados dos Ensaios"))<>"",INDIRECT(ADDRESS(($AK21),COLUMN()+6,,,"Digitar Dados dos Ensaios")),"")) | G21: =IF(OR($N$8="",$N$8=0),"",IF(INDIRECT(ADDRESS(($AK21),COLUMN()+6,,,"Digitar Dados dos Ensaios"))<>"",INDIRECT(ADDRESS(($AK21),COLUMN()+6,,,"Digitar Dados dos Ensaios")),"")) | H21: =IF(OR($N$8="",$N$8=0),"",IF(INDIRECT(ADDRESS(($AK21),COLUMN()+6,,,"Digitar Dados dos Ensaios"))<>"",INDIRECT(ADDRESS(($AK21),COLUMN()+6,,,"Digitar Dados dos Ensaios")),"")) | I21: =IF(OR($N$8="",$N$8=0),"",IF(INDIRECT(ADDRESS(($AK21),COLUMN()+6,,,"Digitar Dados dos Ensaios"))<>"",INDIRECT(ADDRESS(($AK21),COLUMN()+6,,,"Digitar Dados dos Ensaios")),"")) | J21: =IF(OR($N$8="",$N$8=0),"",IF(INDIRECT(ADDRESS(($AK21),COLUMN()+6,,,"Digitar Dados dos Ensaios"))<>"",INDIRECT(ADDRESS(($AK21),COLUMN()+6,,,"Digitar Dados dos Ensaios")),"")) -> 185.17 | K21: =IF(OR($N$8="",$N$8=0),"",IF(INDIRECT(ADDRESS(($AK21),COLUMN()+5,,,"Digitar Dados dos Ensaios"))<>"",INDIRECT(ADDRESS(($AK21),COLUMN()+5,,,"Digitar Dados dos Ensaios")),"")) -> 185.17 | L21: =IF(OR($N$8="",$N$8=0),"",IF(INDIRECT(ADDRESS(($AK21),COLUMN()+5,,,"Digitar Dados dos Ensaios"))<>"",INDIRECT(ADDRESS(($AK21),COLUMN()+5,,,"Digitar Dados dos Ensaios")),"")) -> 200 | AK21: =AK20+1 -> 8 | AZ21: 0 | BA21: =BA14 -> 2219.2469
A22: Peso da Água | C22: g | D22: =IF(D19<>"",D20-D21,"") | E22: =IF(E19<>"",E20-E21,"") | F22: =IF(F19<>"",F20-F21,"") | G22: =IF(G19<>"",G20-G21,"") | H22: =IF(H19<>"",H20-H21,"") | I22: =IF(I18<>"",I20-I21,"") | J22: =IF(J19<>"",J20-J21,"") -> 1.38 | K22: =IF(K19<>"",K20-K21,"") -> 1.38 | L22: =IF(L19<>"",L20-L21,"") -> 1.76 | AZ22: =BA13 -> 0.057765822 | BA22: =BA21 -> 2219.2469
A23: Peso da Cápsula | C23: g | D23: =IF(D19<>"",LOOKUP(D19,Tara!$C$6:$C$185,Tara!$D$6:$D$185),"") | E23: =IF(E19<>"",LOOKUP(E19,Tara!$C$6:$C$185,Tara!$D$6:$D$185),"") | F23: =IF(F19<>"",LOOKUP(F19,Tara!$C$6:$C$185,Tara!$D$6:$D$185),"") | G23: =IF(G19<>"",LOOKUP(G19,Tara!$C$6:$C$185,Tara!$D$6:$D$185),"") | H23: =IF(H19<>"",LOOKUP(H19,Tara!$C$6:$C$185,Tara!$D$6:$D$185),"") | I23: =IF(I18<>"",LOOKUP(I19,Tara!$C$6:$C$185,Tara!$D$6:$D$185),"") | J23: =IF(J19<>"",LOOKUP(J19,Tara!$C$6:$C$185,Tara!$D$6:$D$185),"") -> 24.1 | K23: =IF(K19<>"",LOOKUP(K19,Tara!$C$6:$C$185,Tara!$D$6:$D$185),"") -> 24.1 | L23: =IF(L19<>"",LOOKUP(L19,Tara!$C$6:$C$185,Tara!$D$6:$D$185),"") -> 14.81 | AZ23: =AZ22 -> 0.057765822 | BA23: 0
A24: Peso do Solo Seco | C24: g | D24: =IF(D19<>"",D21-D23,"") | E24: =IF(E19<>"",E21-E23,"") | F24: =IF(F19<>"",F21-F23,"") | G24: =IF(G19<>"",G21-G23,"") | H24: =IF(H19<>"",H21-H23,"") | I24: =IF(I18<>"",I21-I23,"") | J24: =IF(J19<>"",J21-J23,"") -> 161.07 | K24: =IF(K19<>"",K21-K23,"") -> 161.07 | L24: =IF(L19<>"",L21-L23,"") -> 185.19
A25: Umidade | C25: % | D25: =IF(D19<>"",D22/D24,"") | E25: =IF(E19<>"",E22/E24,"") | F25: =IF(F19<>"",F22/F24,"") | G25: =IF(G19<>"",G22/G24,"") | H25: =IF(H19<>"",H22/H24,"") | I25: =IF(I18<>"",I22/I24,"") | J25: =IF(J19<>"",J22/J24,"") -> 0.0085677035 | K25: =IF(K19<>"",K22/K24,"") -> 0.0085677035 | L25: =IF(L19<>"",L22/L24,"") -> 0.0095037529
A26: Umidade Média | C26: % | D26: =IF(ISNUMBER(D27),(D27/$K$30),"") -> 0.023450524 | E26: =IF(ISNUMBER(E27),(E27/$K$30),"") -> 0.03858606 | F26: =IF(ISNUMBER(F27),(F27/$K$30),"") -> 0.053721596 | G26: =IF(ISNUMBER(G27),(G27/$K$30),"") -> 0.068857132 | H26: =IF(ISNUMBER(H27),(H27/$K$30),"") -> 0.083992668 | I26: =IF(ISNUMBER(I27),(I27/$K$30),"") | J26: =IF(ISNUMBER(J27),(J27/$K$30),"") | K26: =IF(ISNUMBER(K25),AVERAGE(K25:L25),"") -> 0.0090357282 | S26: Compactação | W26: Cálculo da Densidade | Y26: Amostra | AB26: =IF(F234+I234>H234,H234,F234+I234) -> 0
A27: Água Total | C27: g | D27: =IF(AND(ISNUMBER(D28),ISNUMBER($K$32)),D28+$K$32,"") -> 162.6837 | E27: =IF(AND(ISNUMBER(E28),ISNUMBER($K$32)),E28+$K$32,"") -> 267.6837 | F27: =IF(AND(ISNUMBER(F28),ISNUMBER($K$32)),F28+$K$32,"") -> 372.6837 | G27: =IF(AND(ISNUMBER(G28),ISNUMBER($K$32)),G28+$K$32,"") -> 477.6837 | H27: =IF(AND(ISNUMBER(H28),ISNUMBER($K$32)),H28+$K$32,"") -> 582.6837 | I27: =IF(AND(ISNUMBER(I18),ISNUMBER($K$32)),I28+$K$32,"") | J27: =IF(AND(ISNUMBER(J28),ISNUMBER($K$32)),J28+$K$32,"") | K27: Peso do Material g | S27: ISC | W27: Pela Higroscopica | Y27: Trabalhada
A28: Água Adicionada | C28: g | D28: =IF(OR($N$8="",$N$8=0),"",IF(INDIRECT(ADDRESS(($AK28),COLUMN()+7,,,"Digitar Dados dos Ensaios"))<>"",INDIRECT(ADDRESS(($AK28),COLUMN()+7,,,"Digitar Dados dos Ensaios")),"")) -> 100 | E28: =IF(AND(ISNUMBER(E29),ISNUMBER($K$28)),E29*$K$28,"") -> 205 | F28: =IF(AND(ISNUMBER(F29),ISNUMBER($K$28)),F29*$K$28,"") -> 310 | G28: =IF(AND(ISNUMBER(G29),ISNUMBER($K$28)),G29*$K$28,"") -> 415 | H28: =IF(AND(ISNUMBER(H29),ISNUMBER($K$28)),H29*$K$28,"") -> 520 | I28: =IF(AND(ISNUMBER(I18),ISNUMBER($K$28)),I29*$K$28,"") | J28: =IF(AND(ISNUMBER(J29),ISNUMBER($K$28)),J29*$K$28,"") | K28: =IF(OR($N$8="",$N$8=0),"",IF(INDIRECT(ADDRESS(($AK28),COLUMN()+6,,,"Digitar Dados dos Ensaios"))<>"",INDIRECT(ADDRESS(($AK28),COLUMN()+6,,,"Digitar Dados dos Ensaios")),"")) -> 7000 | L28: =IF(OR($N$8="",$N$8=0),"",IF(INDIRECT(ADDRESS(($AK28),COLUMN()+6,,,"Digitar Dados dos Ensaios"))<>"",INDIRECT(ADDRESS(($AK28),COLUMN()+6,,,"Digitar Dados dos Ensaios")),"")) -> Moldagem do ISC Ótimo | S28: Expansaão | W28: Pelas Cápsulas | Y28: Não Trabalhada | AK28: =AK21+1 -> 9 | AL28: =IF(OR($N$8="",$N$8=0),"",IF(INDIRECT(ADDRESS(($AK28),COLUMN()-24,,,"Digitar Dados dos Ensaios"))<>"",INDIRECT(ADDRESS(($AK28),COLUMN()-24,,,"Digitar Dados dos Ensaios")),"")) -> 0.015
A29: % Água Adicionada | C29: % | D29: =IF(AND(D31<>0,ISNUMBER(D28)),D28/K28,"") -> 0.014285714 | E29: =IF(AND(ISNUMBER($AL$28),ISNUMBER(E18),E31<>0),D29+$AL$28,"") -> 0.029285714 | F29: =IF(AND(ISNUMBER($AL$28),ISNUMBER(F18),F31<>0),E29+$AL$28,"") -> 0.044285714 | G29: =IF(AND(ISNUMBER($AL$28),ISNUMBER(G18),G31<>0),F29+$AL$28,"") -> 0.059285714 | H29: =IF(AND(ISNUMBER($AL$28),ISNUMBER(H18),H31<>0),G29+$AL$28,"") -> 0.074285714 | I29: =IF(AND(ISNUMBER($AL$28),ISNUMBER(I18),I31<>0),H29+$AL$28,"") | J29: =IF(AND(ISNUMBER($AL$28),ISNUMBER(I29),J31<>0),I29+$AL$28,"") | K29: P. Mat. Seco g
A30: Cilindro Nº | C30: - | D30: =IF(OR($N$8="",$N$8=0),"",IF(INDIRECT(ADDRESS(($AK30),COLUMN()+6,,,"Digitar Dados dos Ensaios"))<>"",INDIRECT(ADDRESS(($AK30),COLUMN()+6,,,"Digitar Dados dos Ensaios")),"")) -> 41 | E30: =IF(OR($N$8="",$N$8=0),"",IF(INDIRECT(ADDRESS(($AK30),COLUMN()+6,,,"Digitar Dados dos Ensaios"))<>"",INDIRECT(ADDRESS(($AK30),COLUMN()+6,,,"Digitar Dados dos Ensaios")),"")) -> 28 | F30: =IF(OR($N$8="",$N$8=0),"",IF(INDIRECT(ADDRESS(($AK30),COLUMN()+6,,,"Digitar Dados dos Ensaios"))<>"",INDIRECT(ADDRESS(($AK30),COLUMN()+6,,,"Digitar Dados dos Ensaios")),"")) -> 46 | G30: =IF(OR($N$8="",$N$8=0),"",IF(INDIRECT(ADDRESS(($AK30),COLUMN()+6,,,"Digitar Dados dos Ensaios"))<>"",INDIRECT(ADDRESS(($AK30),COLUMN()+6,,,"Digitar Dados dos Ensaios")),"")) -> 48 | H30: =IF(OR($N$8="",$N$8=0),"",IF(INDIRECT(ADDRESS(($AK30),COLUMN()+6,,,"Digitar Dados dos Ensaios"))<>"",INDIRECT(ADDRESS(($AK30),COLUMN()+6,,,"Digitar Dados dos Ensaios")),"")) -> 41 | I30: =IF(OR($N$8="",$N$8=0),"",IF(INDIRECT(ADDRESS(($AK30),COLUMN()+6,,,"Digitar Dados dos Ensaios"))<>"",INDIRECT(ADDRESS(($AK30),COLUMN()+6,,,"Digitar Dados dos Ensaios")),"")) | J30: =IF(OR($N$8="",$N$8=0),"",IF(INDIRECT(ADDRESS(($AK30),COLUMN()+6,,,"Digitar Dados dos Ensaios"))<>"",INDIRECT(ADDRESS(($AK30),COLUMN()+6,,,"Digitar Dados dos Ensaios")),"")) -> % Ret.#3/4" | K30: =IF(ISNUMBER(K28),K28/(K26+1),"") -> 6937.3163 | AK30: =AK28+1 -> 10
A31: Peso Bruto Úmido | C31: g | D31: =IF(OR($N$8="",$N$8=0),"",IF(INDIRECT(ADDRESS(($AK31),COLUMN()+6,,,"Digitar Dados dos Ensaios"))<>"",INDIRECT(ADDRESS(($AK31),COLUMN()+6,,,"Digitar Dados dos Ensaios")),"")) -> 9575 | E31: =IF(OR($N$8="",$N$8=0),"",IF(INDIRECT(ADDRESS(($AK31),COLUMN()+6,,,"Digitar Dados dos Ensaios"))<>"",INDIRECT(ADDRESS(($AK31),COLUMN()+6,,,"Digitar Dados dos Ensaios")),"")) -> 9661 | F31: =IF(OR($N$8="",$N$8=0),"",IF(INDIRECT(ADDRESS(($AK31),COLUMN()+6,,,"Digitar Dados dos Ensaios"))<>"",INDIRECT(ADDRESS(($AK31),COLUMN()+6,,,"Digitar Dados dos Ensaios")),"")) -> 10042 | G31: =IF(OR($N$8="",$N$8=0),"",IF(INDIRECT(ADDRESS(($AK31),COLUMN()+6,,,"Digitar Dados dos Ensaios"))<>"",INDIRECT(ADDRESS(($AK31),COLUMN()+6,,,"Digitar Dados dos Ensaios")),"")) -> 10055 | H31: =IF(OR($N$8="",$N$8=0),"",IF(INDIRECT(ADDRESS(($AK31),COLUMN()+6,,,"Digitar Dados dos Ensaios"))<>"",INDIRECT(ADDRESS(($AK31),COLUMN()+6,,,"Digitar Dados dos Ensaios")),"")) -> 10000 | I31: =IF(OR($N$8="",$N$8=0),"",IF(INDIRECT(ADDRESS(($AK31),COLUMN()+6,,,"Digitar Dados dos Ensaios"))<>"",INDIRECT(ADDRESS(($AK31),COLUMN()+6,,,"Digitar Dados dos Ensaios")),"")) | J31: =IF(OR($N$8="",$N$8=0),"",IF(INDIRECT(ADDRESS(($AK31),COLUMN()+6,,,"Digitar Dados dos Ensaios"))<>"",INDIRECT(ADDRESS(($AK31),COLUMN()+6,,,"Digitar Dados dos Ensaios")),"")) -> % Ret.# nº4 | K31: Peso Água g | AK31: =AK30+1 -> 11
A32: Peso do Cilindro | C32: g | D32: =IF(D30<>"",LOOKUP(D30,Tara!$G$6:$G$185,Tara!$H$6:$H$185),"") -> 5530 | E32: =IF(E30<>"",LOOKUP(E30,Tara!$G$6:$G$185,Tara!$H$6:$H$185),"") -> 5294 | F32: =IF(F30<>"",LOOKUP(F30,Tara!$G$6:$G$185,Tara!$H$6:$H$185),"") -> 5222 | G32: =IF(G30<>"",LOOKUP(G30,Tara!$G$6:$G$185,Tara!$H$6:$H$185),"") -> 5130 | H32: =IF(H30<>"",LOOKUP(H30,Tara!$G$6:$G$185,Tara!$H$6:$H$185),"") -> 5530 | I32: =IF(I18<>"",LOOKUP(I30,Tara!$G$6:$G$185,Tara!$H$6:$H$185),"") | J32: =IF(J30<>"",LOOKUP(J30,Tara!$G$6:$G$185,Tara!$H$6:$H$185),"") -> #N/A | K32: =IF(K28<>"",K28-K30,"") -> 62.683704 | L32: =IF(ISNUMBER(J30),J30-J32,"")
A33: Volume do Cilindro | D33: =IF(D30<>"",LOOKUP(D30,Tara!$G$6:$G$185,Tara!$I$6:$I$185),"") -> 2082 | E33: =IF(E30<>"",LOOKUP(E30,Tara!$G$6:$G$185,Tara!$I$6:$I$185),"") -> 2083 | F33: =IF(F30<>"",LOOKUP(F30,Tara!$G$6:$G$185,Tara!$I$6:$I$185),"") -> 2037 | G33: =IF(G30<>"",LOOKUP(G30,Tara!$G$6:$G$185,Tara!$I$6:$I$185),"") -> 2068 | H33: =IF(H30<>"",LOOKUP(H30,Tara!$G$6:$G$185,Tara!$I$6:$I$185),"") -> 2082 | I33: =IF(I18<>"",LOOKUP(I30,Tara!$G$6:$G$185,Tara!$I$6:$I$185),"") | J33: =IF(J30<>"",LOOKUP(J30,Tara!$G$6:$G$185,Tara!$I$6:$I$185),"") -> #N/A
A34: Peso do Solo Úmido | C34: g | D34: =IF(D31<>"",D31-D32,"") -> 4045 | E34: =IF(E31<>"",E31-E32,"") -> 4367 | F34: =IF(F31<>"",F31-F32,"") -> 4820 | G34: =IF(G31<>"",G31-G32,"") -> 4925 | H34: =IF(H31<>"",H31-H32,"") -> 4470 | I34: =IF(I18<>"",I31-I32,"") | J34: =IF(J31<>"",J31-J32,"") -> #VALUE! | AC34: =D26 -> 0.023450524 | AD34: =E26 -> 0.03858606 | AE34: =F26 -> 0.053721596 | AF34: =G26 -> 0.068857132 | AG34: =H26 -> 0.083992668
A35: Dens. Solo Úmido | C35: g / m³ | D35: =IF(D34<>"",D34*1000/D33,"") -> 1942.8434 | E35: =IF(E34<>"",E34*1000/E33,"") -> 2096.4954 | F35: =IF(F34<>"",F34*1000/F33,"") -> 2366.2248 | G35: =IF(G34<>"",G34*1000/G33,"") -> 2381.528 | H35: =IF(H34<>"",H34*1000/H33,"") -> 2146.9741 | I35: =IF(I34<>"",I34*1000/I33,"") | J35: =IF(J34<>"",J34*1000/J33,"") -> #VALUE!
A36: Dens. Solo Seco | C36: g / m³ | D36: =IF(D35="","",IF($AS$7=TRUE,D35/(1+D26),IF($AS$8=TRUE,D35/(1+D25),""))) -> 1898.3267 | E36: =IF(E35="","",IF($AS$7=TRUE,E35/(1+E26),IF($AS$8=TRUE,E35/(1+E25),""))) -> 2018.6054 | F36: =IF(F35="","",IF($AS$7=TRUE,F35/(1+F26),IF($AS$8=TRUE,F35/(1+F25),""))) -> 2245.5883 | G36: =IF(G35="","",IF($AS$7=TRUE,G35/(1+G26),IF($AS$8=TRUE,G35/(1+G25),""))) -> 2228.107 | H36: =IF(H35="","",IF($AS$7=TRUE,H35/(1+H26),IF($AS$8=TRUE,H35/(1+H25),""))) -> 1980.6168 | I36: =IF(I35="","",IF($AS$7=TRUE,I35/(1+I26),IF($AS$8=TRUE,I35/(1+I25),""))) | J36: =IF(J35="","",IF($AS$7=TRUE,J35/(1+J26),IF($AS$8=TRUE,J35/(1+J25),""))) -> #VALUE!
A37: Resultados: | E37: Obs:
A39: U. Ótima | B39: Dens. Máx | C39: ISC | D39: Expansão
A40: =IF(ISERROR(BA13),"",BA13) -> 0.057765822 | B40: =IF(ISERROR(BA14),"",BA14) -> 2219.2469 | C40: =IF(ISERROR(BB94),"",BB94) | D40: =IF(ISERROR(BB103),"",BB103) | AC40: =D32 -> 5530 | AD40: =E32 -> 5294 | AE40: =F32 -> 5222 | AF40: =G32 -> 5130 | AG40: =H32 -> 5530
AC41: =D33 -> 2082 | AD41: =E33 -> 2083 | AE41: =F33 -> 2037 | AF41: =G33 -> 2068 | AG41: =H33 -> 2082
AC43: =AC44+AC40 -> 9689.2587 | AD43: =AD44+AD40 -> 9734.8344 | AE43: =AE44+AE40 -> 9710.187 | AF43: =AF44+AF40 -> 9702.4844 | AG43: =AG44+AG40 -> 10019.3
AC44: =AC45*AC41/1000 -> 4159.2587 | AD44: =AD45*AD41/1000 -> 4440.8344 | AE44: =AE45*AE41/1000 -> 4488.187 | AF44: =AF45*AF41/1000 -> 4572.4844 | AG44: =AG45*AG41/1000 -> 4489.2997
...

Sheet Digitar Dados dos Ensaios
A1: BR -163 | F1: Compactação | T1: ISC & EXPANSÃO | Z1: LEITURA DO EXTENSÔMETRO | AD1: LEITURA DA PRENSA | AL1: LIMITES FÍSICOS | AT1: GRANULOMETRIA & EQUIVALENTE DE AREIA | BM1: Cálculos Para Compactação
A2: Nova Mutum- MT
AD4: 0.63 | AE4: 1.27 | AF4: 1.9 | AG4: 2.54 | AH4: 3.81 | AI4: 5.08 | AJ4: 6.35 | AK4: 7.62 | BM4: Cálculos não Ultrapasse
A5: 1 | B5: ORIGEM DA AMOSTRA | F5: Númere os Pontos Executados (de 1 a 6) | J5: 1 | K5: 2 | L5: 3 | M5: 4 | N5: 5 | P5: Umidade Higroscópica | R5: Umidade. de Moldagem | T5: Pontos | U5: Cilindro Nº | V5: Hora da Leitura | Z5: Leitura | AD5: 0.5 | AE5: 1 | AF5: 1.5 | AG5: 2 | AH5: 3 | AI5: 4 | AJ5: 5 | AK5: 6 | AL5: Limite de Liquidez | AM5: Cápsula nº | AS5: =E7 -> 45804 | AT5: Umidade Higrocópica | AZ5: Peneiramento Grosso | BG5: Total | BH5: Parcial | BI5: Peneiramento Fino | BL5: =AS5 -> 45804 | BM5: Atenção | BN5: Peso da Água | BO5: =IF(ISNUMBER(J6),J7-J8,"") | BP5: =IF(ISNUMBER(K6),K7-K8,"") | BQ5: =IF(ISNUMBER(L6),L7-L8,"") | BR5: =IF(ISNUMBER(M6),M7-M8,"") | BS5: =IF(ISNUMBER(N6),N7-N8,"") | BT5: =IF(ISNUMBER(O6),O7-O8,"") | BU5: =IF(ISNUMBER(P6),P7-P8,"") -> 1.38 | BV5: =IF(ISNUMBER(Q6),Q7-Q8,"") -> 1.76 | BW5: =IF(ISNUMBER(BU5),AVERAGE(BU8:BV8),"") -> 0.0090357282 | BX5: Cilindros | CE5: =IF(J5<>"",BY10,"") -> 0.023450524 | CF5: =IF(K5<>"",BZ10,"") -> 0.03858606 | CG5: =IF(L5<>"",CA10,"") -> 0.053721596 | CH5: =IF(M5<>"",CB10,"") -> 0.068857132 | CI5: =IF(N5<>"",CC10,"") -> 0.083992668 | CJ5: =IF(O5<>"",CD10,"") | CK5: =AVERAGE(CE5:CJ5) -> 0.053721596 | CL5: =IF(ISNUMBER(CE8),CE8^2,"") -> 0.00091633779 | CM5: =IF(ISNUMBER(CF8),CF8^2,"") -> 0.00022908445 | CN5: =IF(ISNUMBER(CG8),CG8^2,"") -> 0 | CO5: =IF(ISNUMBER(CH8),CH8^2,"") -> 0.00022908445 | CP5: =IF(ISNUMBER(CI8),CI8^2,"") -> 0.00091633779 | CQ5: =IF(ISNUMBER(CJ8),CJ8^2,"") | CR5: =SUM(CL5:CQ5) -> 0.0022908445 | CS5: x= | CT5: =-CO11/(2*CM11) -> 0.057765822 | CU5: =IF(ISNUMBER(R6),R7-R8,"") | CV5: =IF(ISNUMBER(S6),S7-S8,"") | CW5: =IF(ISNUMBER(CU5),AVERAGE(CU8:CV8),"") | CX5: 0.63 | CY5: 1.27 | CZ5: 1.9 | DA5: 2.54 | DB5: 3.81 | DC5: 5.08 | DD5: 6.35 | DE5: 7.62 | DF5: =IF(CX6<>"",AVERAGE(CX5:DE5),"") | DG5: =IF(ISNUMBER(CX10),CX10^2,"") | DH5: =IF(ISNUMBER(CY10),CY10^2,"") | DI5: =IF(ISNUMBER(CZ10),CZ10^2,"") | DJ5: =IF(ISNUMBER(DA10),DA10^2,"") | DK5: =IF(ISNUMBER(DB10),DB10^2,"") | DL5: =IF(ISNUMBER(DC10),DC10^2,"") | DM5: =IF(ISNUMBER(DD10),DD10^2,"") | DN5: =IF(ISNUMBER(DE10),DE10^2,"") | DO5: =IF(DG5<>"",SUM(DG5:DN5),"") | DP5: 0 | DQ5: =IF(DP6="","",IF(DP6>0,DT8,-1)) | DR5: =IF(DP6="","",IF(DP6>0,DV8,-1)) | DS5: =IF(DP6="","",IF(DP6>0,(DJ9*DS6)+DJ10,-1)) | DT5: =IF(DP6="","",IF(DP6>0,(DJ9*DT6)+DJ10,-1)) | DU5: =IF(DP6="","",IF(DP6>0,DT8,-1)) | DV5: =IF(DP6="","",IF(DP6>0,DT8,-1)) | DW5: =IF(DP6="","",IF(DP6>0,DT8,-1)) | DX5: =IF(DP6="","",IF(DP6>0,DS5,-1)) | DY5: 0.63 | DZ5: 1.27 | EA5: 1.9 | EB5: 2.54 | EC5: 3.81 | ED5: 5.08 | EE5: 6.35 | EF5: 7.62 | EG5: =IF(DY6<>"",AVERAGE(DY5:EF5),"") -> 3.65 | EH5: =IF(ISNUMBER(DY10),DY10^2,"") -> 340.42833 | EI5: =IF(ISNUMBER(DZ10),DZ10^2,"") -> 297.03488 | EJ5: =IF(ISNUMBER(EA10),EA10^2,"") -> 232.18445 | EK5: =IF(ISNUMBER(EB10),EB10^2,"") -> 153.66082 | EL5: =IF(ISNUMBER(EC10),EC10^2,"") -> 18.761892 | EM5: =IF(ISNUMBER(ED10),ED10^2,"") -> 48.424897 | EN5: =IF(ISNUMBER(EE10),EE10^2,"") -> 461.17133 | EO5: =IF(ISNUMBER(EF10),EF10^2,"") -> 1537.9574 | EP5: =IF(EH5<>"",SUM(EH5:EO5),"") -> 3089.624 | EQ5: 0 | ER5: =IF(EQ6="","",IF(EQ6>0,EU8,-1)) -> -1 | ES5: =IF(EQ6="","",IF(EQ6>0,EW8,-1)) -> -1 | ET5: =IF(EQ6="","",IF(EQ6>0,(EK9*ET6)+EK10,-1)) -> -1 | EU5: =IF(EQ6="","",IF(EQ6>0,(EK9*EU6)+EK10,-1)) -> -1 | EV5: =IF(EQ6="","",IF(EQ6>0,EU8,-1)) -> -1 | EW5: =IF(EQ6="","",IF(EQ6>0,EU8,-1)) -> -1 | EX5: =IF(EQ6="","",IF(EQ6>0,EU8,-1)) -> -1 | EY5: =IF(EQ6="","",IF(EQ6>0,ET5,-1)) -> -1 | EZ5: 0.63 | FA5: 1.27 | FB5: 1.9 | FC5: 2.54 | FD5: 3.81 | FE5: 5.08 | FF5: 6.35 | FG5: 7.62 | FH5: =IF(EZ6<>"",AVERAGE(EZ5:FG5),"") -> 3.65 | FI5: =IF(ISNUMBER(EZ10),EZ10^2,"") -> 340.42833 | FJ5: =IF(ISNUMBER(FA10),FA10^2,"") -> 297.03488 | FK5: =IF(ISNUMBER(FB10),FB10^2,"") -> 232.18445 | FL5: =IF(ISNUMBER(FC10),FC10^2,"") -> 153.66082 | FM5: =IF(ISNUMBER(FD10),FD10^2,"") -> 18.761892 | FN5: =IF(ISNUMBER(FE10),FE10^2,"") -> 48.424897 | FO5: =IF(ISNUMBER(FF10),FF10^2,"") -> 461.17133 | FP5: =IF(ISNUMBER(FG10),FG10^2,"") -> 1537.9574 | FQ5: =IF(FI5<>"",SUM(FI5:FP5),"") -> 3089.624 | FR5: 0 | FS5: =IF(FR6="","",IF(FR6>0,FV8,-1)) -> -1 | FT5: =IF(FR6="","",IF(FR6>0,FX8,-1)) -> -1 | FU5: =IF(FR6="","",IF(FR6>0,(FL9*FU6)+FL10,-1)) -> -1 | FV5: =IF(FR6="","",IF(FR6>0,(FL9*FV6)+FL10,-1)) -> -1 | FW5: =IF(FR6="","",IF(FR6>0,FV8,-1)) -> -1 | FX5: =IF(FR6="","",IF(FR6>0,FV8,-1)) -> -1 | FY5: =IF(FR6="","",IF(FR6>0,FV8,-1)) -> -1 | FZ5: =IF(FR6="","",IF(FR6>0,FU5,-1)) -> -1 | GA5: 0.63 | GB5: 1.27 | GC5: 1.9 | GD5: 2.54 | GE5: 3.81 | GF5: 5.08 | GG5: 6.35 | GH5: 7.62 | GI5: =IF(GA6<>"",AVERAGE(GA5:GH5),"") -> 3.65 | GJ5: =IF(ISNUMBER(GA10),GA10^2,"") -> 340.42833 | GK5: =IF(ISNUMBER(GB10),GB10^2,"") -> 297.03488 | GL5: =IF(ISNUMBER(GC10),GC10^2,"") -> 232.18445 | GM5: =IF(ISNUMBER(GD10),GD10^2,"") -> 153.66082 | GN5: =IF(ISNUMBER(GE10),GE10^2,"") -> 18.761892 | GO5: =IF(ISNUMBER(GF10),GF10^2,"") -> 48.424897 | GP5: =IF(ISNUMBER(GG10),GG10^2,"") -> 461.17133 | GQ5: =IF(ISNUMBER(GH10),GH10^2,"") -> 1537.9574 | GR5: =IF(GJ5<>"",SUM(GJ5:GQ5),"") -> 3089.624 | GS5: 0 | GT5: =IF(GS6="","",IF(GS6>0,GW8,-1)) -> -1 | GU5: =IF(GS6="","",IF(GS6>0,GY8,-1)) -> -1 | GV5: =IF(GS6="","",IF(GS6>0,(GM9*GV6)+GM10,-1)) -> -1 | GW5: =IF(GS6="","",IF(GS6>0,(GM9*GW6)+GM10,-1)) -> -1 | GX5: =IF(GS6="","",IF(GS6>0,GW8,-1)) -> -1 | GY5: =IF(GS6="","",IF(GS6>0,GW8,-1)) -> -1 | GZ5: =IF(GS6="","",IF(GS6>0,GW8,-1)) -> -1 | HA5: =IF(GS6="","",IF(GS6>0,GV5,-1)) -> -1 | HB5: 0.63 | HC5: 1.27 | HD5: 1.9 | HE5: 2.54 | HF5: 3.81 | HG5: 5.08 | HH5: 6.35 | HI5: 7.62 | HJ5: =IF(HB6<>"",AVERAGE(HB5:HI5),"") | HK5: =IF(ISNUMBER(HB10),HB10^2,"") | HL5: =IF(ISNUMBER(HC10),HC10^2,"") | HM5: =IF(ISNUMBER(HD10),HD10^2,"") | HN5: =IF(ISNUMBER(HE10),HE10^2,"") | HO5: =IF(ISNUMBER(HF10),HF10^2,"") | HP5: =IF(ISNUMBER(HG10),HG10^2,"") | HQ5: =IF(ISNUMBER(HH10),HH10^2,"") | HR5: =IF(ISNUMBER(HI10),HI10^2,"") | HS5: =IF(HK5<>"",SUM(HK5:HR5),"") | HT5: 0 | HU5: =IF(HT6="","",IF(HT6>0,HX8,-1)) | HV5: =IF(HT6="","",IF(HT6>0,HZ8,-1)) | HW5: =IF(HT6="","",IF(HT6>0,(HN9*HW6)+HN10,-1)) | HX5: =IF(HT6="","",IF(HT6>0,(HN9*HX6)+HN10,-1)) | HY5: =IF(HT6="","",IF(HT6>0,HX8,-1)) | HZ5: =IF(HT6="","",IF(HT6>0,HX8,-1)) | IA5: =IF(HT6="","",IF(HT6>0,HX8,-1)) | IB5: =IF(HT6="","",IF(HT6>0,HW5,-1)) | IC5: 0.63 | ID5: 1.27 | IE5: 1.9 | IF5: 2.54 | IG5: 3.81 | IH5: 5.08 | II5: 6.35 | IJ5: 7.62 | IK5: =IF(IC6<>"",AVERAGE(IC5:IJ5),"") | IL5: =IF(ISNUMBER(IC10),IC10^2,"") | IM5: =IF(ISNUMBER(ID10),ID10^2,"") | IN5: =IF(ISNUMBER(IE10),IE10^2,"") | IO5: =IF(ISNUMBER(IF10),IF10^2,"") | IP5: =IF(ISNUMBER(IG10),IG10^2,"") | IQ5: =IF(ISNUMBER(IH10),IH10^2,"") | IR5: =IF(ISNUMBER(II10),II10^2,"") | IS5: =IF(ISNUMBER(IJ10),IJ10^2,"") | IT5: =IF(IL5<>"",SUM(IL5:IS5),"") | IU5: 0 | IV5: =IF(IU6="","",IF(IU6>0,IY8,-1)) | IW5: =IF(IU6="","",IF(IU6>0,JA8,-1)) | IX5: =IF(IU6="","",IF(IU6>0,(IO9*IX6)+IO10,-1)) | IY5: =IF(IU6="","",IF(IU6>0,(IO9*IY6)+IO10,-1)) | IZ5: =IF(IU6="","",IF(IU6>0,IY8,-1)) | JA5: =IF(IU6="","",IF(IU6>0,IY8,-1)) | JB5: =IF(IU6="","",IF(IU6>0,IY8,-1)) | JC5: =IF(IU6="","",IF(IU6>0,IX5,-1)) | JD5: =IF(T6<>"",T6,"") | JE5: =IF(JD5<>"",CE5,"") | JF5: =IF(JD6<>"",CF5,"") -> 0.03858606 | JG5: =IF(JD7<>"",CG5,"") -> 0.053721596 | JH5: =IF(JD8<>"",CH5,"") -> 0.068857132 | JI5: =IF(JD9<>"",CI5,"") | JJ5: =IF(JD10<>"",CJ5,"") | JK5: =AVERAGE(JE5:JJ5) -> 0.053721596 | JL5: =IF(ISNUMBER(JE8),JE8^2,"") | JM5: =IF(ISNUMBER(JF8),JF8^2,"") -> 0.00022908445 | JN5: =IF(ISNUMBER(JG8),JG8^2,"") -> 0 | JO5: =IF(ISNUMBER(JH8),JH8^2,"") -> 0.00022908445 | JP5: =IF(ISNUMBER(JI8),JI8^2,"") | JQ5: =IF(ISNUMBER(JJ8),JJ8^2,"") | JR5: =SUM(JL5:JQ5) -> 0.0004581689 | JS5: x= | JT5: =-JO11/(2*JM11) -> 0.055061915 | JU5: =IF(T6<>0,LOOKUP(T6,Tara!$G$6:$G$185,Tara!$J$6:$J$185)/10,"") | JV5: =IF(ISNUMBER(U6),MAX(Z6:AC6)-MIN(Z6:AC6),"") | JW5: =IF(JV5<>"",JV5/JU5/10,"") | JX5: =IF(JD5<>"",CE5,"") | JY5: =IF(JD6<>"",CF5,"") -> 0.03858606 | JZ5: =IF(JD7<>"",CG5,"") -> 0.053721596 | KA5: =IF(JD8<>"",CH5,"") -> 0.068857132 | KB5: =IF(JD9<>"",CI5,"") | KC5: =IF(JD10<>"",CJ5,"") | KD5: =AVERAGE(JX5:KC5) -> 0.053721596 | KE5: =IF(ISNUMBER(JX8),JX8^2,"") | KF5: =IF(ISNUMBER(JY8),JY8^2,"") -> 0.00022908445 | KG5: =IF(ISNUMBER(JZ8),JZ8^2,"") -> 0 | KH5: =IF(ISNUMBER(KA8),KA8^2,"") -> 0.00022908445 | KI5: =IF(ISNUMBER(KB8),KB8^2,"") | KJ5: =IF(ISNUMBER(KC8),KC8^2,"") | KK5: =SUM(KE5:KJ5) -> 0.0004581689 | KL5: x= | KM5: =-KH11/(2*KF11) -> 0.062952474 | KN5: =IF(ISNUMBER(AN5),AN6-AN7,"") | KO5: =IF(ISNUMBER(AO5),AO6-AO7,"") | KP5: =IF(ISNUMBER(AP5),AP6-AP7,"") | KQ5: =IF(ISNUMBER(AQ5),AQ6-AQ7,"") | KR5: =IF(ISNUMBER(AR5),AR6-AR7,"") | KS5: =IF(ISNUMBER(AN9),AN10-AN11,"") | KT5: =IF(ISNUMBER(AO9),AO10-AO11,"") | KU5: =IF(ISNUMBER(AP9),AP10-AP11,"") | KV5: =IF(ISNUMBER(AQ9),AQ10-AQ11,"") | KW5: =IF(ISNUMBER(AR9),AR10-AR11,"") | KX5: =IF(KU10="NP",0,KU10)*100 -> 0 | KY5: 1 | KZ5: 2 | LA5: =IF(ISNUMBER(AT9),AU9-AV9,"") -> 0 | LB5: =IF(ISNUMBER(AW9),AX9-AY9,"") -> 0 | LE5: 2" | LF5: 1 ½" | LG5: 1" | LH5: ¾" | LI5: 3/8" | LJ5: 4 | LK5: 10 | LL5: 40 | LM5: 200
B6: Estaca: | D6: Registro : | E6: 1 | F6: Marque com X se a Compactação é | G6: Simples | I6: Nº da Cápsula | P6: 10 | Q6: 21 | V6: 0.45833333 | AM6: Cápsula+solo úmido | AT6: Cápsula 01 | AW6: Cápsula 02 | AZ6: Retido | BG6: Amostra | BH6: Peso | BI6: Retido | BN6: Peso da Cápsula | BO6: =IF(ISNUMBER(J6),LOOKUP(J6,Tara!$C$6:$C$185,Tara!$D$6:$D$185),"") | BP6: =IF(ISNUMBER(K6),LOOKUP(K6,Tara!$C$6:$C$185,Tara!$D$6:$D$185),"") | BQ6: =IF(ISNUMBER(L6),LOOKUP(L6,Tara!$C$6:$C$185,Tara!$D$6:$D$185),"") | BR6: =IF(ISNUMBER(M6),LOOKUP(M6,Tara!$C$6:$C$185,Tara!$D$6:$D$185),"") | BS6: =IF(ISNUMBER(N6),LOOKUP(N6,Tara!$C$6:$C$185,Tara!$D$6:$D$185),"") | BT6: =IF(ISNUMBER(O6),LOOKUP(O6,Tara!$C$6:$C$185,Tara!$D$6:$D$185),"") | BU6: =IF(ISNUMBER(P6),LOOKUP(P6,Tara!$C$6:$C$185,Tara!$D$6:$D$185),"") -> 24.1 | BV6: =IF(ISNUMBER(Q6),LOOKUP(Q6,Tara!$C$6:$C$185,Tara!$D$6:$D$185),"") -> 14.81 | BX6: Peso do Cilindro | BY6: =IF(ISNUMBER(J10),LOOKUP(J10,Tara!$G$6:$G$185,Tara!$H$6:$H$185),"") -> 5530 | BZ6: =IF(ISNUMBER(K10),LOOKUP(K10,Tara!$G$6:$G$185,Tara!$H$6:$H$185),"") -> 5294 | CA6: =IF(ISNUMBER(L10),LOOKUP(L10,Tara!$G$6:$G$185,Tara!$H$6:$H$185),"") -> 5222 | CB6: =IF(ISNUMBER(M10),LOOKUP(M10,Tara!$G$6:$G$185,Tara!$H$6:$H$185),"") -> 5130 | CC6: =IF(ISNUMBER(N10),LOOKUP(N10,Tara!$G$6:$G$185,Tara!$H$6:$H$185),"") -> 5530 | CD6: =IF(ISNUMBER(O10),LOOKUP(O10,Tara!$G$6:$G$185,Tara!$H$6:$H$185),"") | CE6: =IF(J5<>"",BY11,"") -> 1898.3267 | CF6: =IF(K5<>"",BZ11,"") -> 2018.6054 | CG6: =IF(L5<>"",CA11,"") -> 2245.5883 | CH6: =IF(M5<>"",CB11,"") -> 2228.107 | CI6: =IF(N5<>"",CC11,"") -> 1980.6168 | CJ6: =IF(O5<>"",CD11,"") | CK6: =AVERAGE(CE6:CJ6) -> 2074.2488 | CL6: =IF(ISNUMBER(CE10),CE10^2,"") -> 7.8078426e-06 | CM6: =IF(ISNUMBER(CF10),CF10^2,"") -> 3.4421186e-06 | CN6: =IF(ISNUMBER(CG10),CG10^2,"") -> 2.0991874e-07 | CO6: =IF(ISNUMBER(CH10),CH10^2,"") -> 1.9519606e-06 | CP6: =IF(ISNUMBER(CI10),CI10^2,"") -> 1.3768474e-05 | CQ6: =IF(ISNUMBER(CJ10),CJ10^2,"") | CR6: =SUM(CL6:CQ6) -> 2.7180315e-05 | CS6: y= | CT6: =CM11*CT5^2+CO11*CT5+CQ11 -> 2219.2469 | CU6: =IF(ISNUMBER(R6),LOOKUP(R6,Tara!$C$6:$C$185,Tara!$D$6:$D$185),"") | CV6: =IF(ISNUMBER(S6),LOOKUP(S6,Tara!$C$6:$C$185,Tara!$D$6:$D$185),"") | CX6: =IF(ISNUMBER(AD6),AD6*$W9,"") | CY6: =IF(ISNUMBER(AE6),AE6*$W9,"") | CZ6: =IF(ISNUMBER(AF6),AF6*$W9,"") | DA6: =IF(ISNUMBER(AG6),AG6*$W9,"") | DB6: =IF(ISNUMBER(AH6),AH6*$W9,"") | DC6: =IF(ISNUMBER(AI6),AI6*$W9,"") | DD6: =IF(ISNUMBER(AJ6),AJ6*$W9,"") | DE6: =IF(ISNUMBER(AK6),AK6*$W9,"") | DF6: =IF(CX6<>"",AVERAGE(CX6:DE6),"") | DG6: =IF(ISERROR(CX8*CX9),"",CX8*CX9) | DH6: =IF(ISERROR(CY8*CY9),"",CY8*CY9) | DI6: =IF(ISERROR(CZ8*CZ9),"",CZ8*CZ9) | DJ6: =IF(ISERROR(DA8*DA9),"",DA8*DA9) | DK6: =IF(ISERROR(DB8*DB9),"",DB8*DB9) | DL6: =IF(ISERROR(DC8*DC9),"",DC8*DC9) | DM6: =IF(ISERROR(DD8*DD9),"",DD8*DD9) | DN6: =IF(ISERROR(DE8*DE9),"",DE8*DE9) | DO6: =IF(DG6<>"",SUM(DG6:DN6),"") | DP6: =IF(DJ10<>"",(DP5-DJ10)/DJ9,"") | DQ6: =IF(DP6="","",IF(DP6>0,DT7+DP6,-1)) | DR6: =IF(DP6="","",IF(DP6>0,DV7+DP6,-1)) | DS6: =IF(DP6="","",IF(DP6>0,DQ6,-1)) | DT6: =IF(DP6="","",IF(DP6>0,DR6,-1)) | DU6: =IF(DP6="","",IF(DP6>0,DT7,-1)) | DV6: =IF(DP6="","",IF(DP6>0,DQ6,-1)) | DW6: =IF(DP6="","",IF(DP6>0,DS6,-1)) | DX6: =IF(DP6="","",IF(DP6>0,DS6,-1)) | DY6: =IF(ISNUMBER(AD7),AD7*$W9,"") -> 3715.2 | DZ6: =IF(ISNUMBER(AE7),AE7*$W9,"") -> 6288.75 | EA6: =IF(ISNUMBER(AF7),AF7*$W9,"") -> 7933.5 | EB6: =IF(ISNUMBER(AG7),AG7*$W9,"") -> 10565.1 | EC6: =IF(ISNUMBER(AH7),AH7*$W9,"") -> 13738.5 | ED6: =IF(ISNUMBER(AI7),AI7*$W9,"") -> 15847.65 | EE6: =IF(ISNUMBER(AJ7),AJ7*$W9,"") -> 17956.8 | EF6: =IF(ISNUMBER(AK7),AK7*$W9,"") -> 20878.65 | EG6: =IF(DY6<>"",AVERAGE(DY6:EF6),"") -> 12115.519 | EH6: =IF(ISERROR(DY8*DY9),"",DY8*DY9) -> 25368.963 | EI6: =IF(ISERROR(DZ8*DZ9),"",DZ8*DZ9) -> 13867.71 | EJ6: =IF(ISERROR(EA8*EA9),"",EA8*EA9) -> 7318.5328 | EK6: =IF(ISERROR(EB8*EB9),"",EB8*EB9) -> 1720.9648 | EL6: =IF(ISERROR(EC8*EC9),"",EC8*EC9) -> 259.677 | EM6: =IF(ISERROR(ED8*ED9),"",ED8*ED9) -> 5336.9477 | EN6: =IF(ISERROR(EE8*EE9),"",EE8*EE9) -> 15771.459 | EO6: =IF(ISERROR(EF8*EF9),"",EF8*EF9) -> 34789.631 | EP6: =IF(EH6<>"",SUM(EH6:EO6),"") -> 104433.89 | EQ6: =IF(EK10<>"",(EQ5-EK10)/EK9,"") -> -1.5568999 | ER6: =IF(EQ6="","",IF(EQ6>0,EU7+EQ6,-1)) -> -1 | ES6: =IF(EQ6="","",IF(EQ6>0,EW7+EQ6,-1)) -> -1 | ET6: =IF(EQ6="","",IF(EQ6>0,ER6,-1)) -> -1 | EU6: =IF(EQ6="","",IF(EQ6>0,ES6,-1)) -> -1 | EV6: =IF(EQ6="","",IF(EQ6>0,EU7,-1)) -> -1 | EW6: =IF(EQ6="","",IF(EQ6>0,ER6,-1)) -> -1 | EX6: =IF(EQ6="","",IF(EQ6>0,ET6,-1)) -> -1 | EY6: =IF(EQ6="","",IF(EQ6>0,ET6,-1)) -> -1 | EZ6: =IF(ISNUMBER(AD8),AD8*$W9,"") -> 3889.35 | FA6: =IF(ISNUMBER(AE8),AE8*$W9,"") -> 8146.35 | FB6: =IF(ISNUMBER(AF8),AF8*$W9,"") -> 12035.7 | FC6: =IF(ISNUMBER(AG8),AG8*$W9,"") -> 14164.2 | FD6: =IF(ISNUMBER(AH8),AH8*$W9,"") -> 17705.25 | FE6: =IF(ISNUMBER(AI8),AI8*$W9,"") -> 21246.3 | FF6: =IF(ISNUMBER(AJ8),AJ8*$W9,"") -> 24439.05 | FG6: =IF(ISNUMBER(AK8),AK8*$W9,"") -> 26915.85 | FH6: =IF(EZ6<>"",AVERAGE(EZ6:FG6),"") -> 16067.756 | FI6: =IF(ISERROR(EZ8*EZ9),"",EZ8*EZ9) -> 36778.787 | FJ6: =IF(ISERROR(FA8*FA9),"",FA8*FA9) -> 18852.947 | FK6: =IF(ISERROR(FB8*FB9),"",FB8*FB9) -> 7056.0984 | FL6: =IF(ISERROR(FC8*FC9),"",FC8*FC9) -> 2112.9474 | FM6: =IF(ISERROR(FD8*FD9),"",FD8*FD9) -> 261.999 | FN6: =IF(ISERROR(FE8*FE9),"",FE8*FE9) -> 7405.3176 | FO6: =IF(ISERROR(FF8*FF9),"",FF8*FF9) -> 22602.493 | FP6: =IF(ISERROR(FG8*FG9),"",FG8*FG9) -> 43066.932 | FQ6: =IF(FI6<>"",SUM(FI6:FP6),"") -> 138137.52 | FR6: =IF(FL10<>"",(FR5-FL10)/FL9,"") -> -1.5994704 | FS6: =IF(FR6="","",IF(FR6>0,FV7+FR6,-1)) -> -1 | FT6: =IF(FR6="","",IF(FR6>0,FX7+FR6,-1)) -> -1 | FU6: =IF(FR6="","",IF(FR6>0,FS6,-1)) -> -1 | FV6: =IF(FR6="","",IF(FR6>0,FT6,-1)) -> -1 | FW6: =IF(FR6="","",IF(FR6>0,FV7,-1)) -> -1 | FX6: =IF(FR6="","",IF(FR6>0,FS6,-1)) -> -1 | FY6: =IF(FR6="","",IF(FR6>0,FU6,-1)) -> -1 | FZ6: =IF(FR6="","",IF(FR6>0,FU6,-1)) -> -1 | GA6: =IF(ISNUMBER(AD9),AD9*$W9,"") -> 2902.5 | GB6: =IF(ISNUMBER(AE9),AE9*$W9,"") -> 5824.35 | GC6: =IF(ISNUMBER(AF9),AF9*$W9,"") -> 9597.6 | GD6: =IF(ISNUMBER(AG9),AG9*$W9,"") -> 11648.7 | GE6: =IF(ISNUMBER(AH9),AH9*$W9,"") -> 15712.2 | GF6: =IF(ISNUMBER(AI9),AI9*$W9,"") -> 17453.7 | GG6: =IF(ISNUMBER(AJ9),AJ9*$W9,"") -> 19795.05 | GH6: =IF(ISNUMBER(AK9),AK9*$W9,"") -> 22697.55 | GI6: =IF(GA6<>"",AVERAGE(GA6:GH6),"") -> 13203.956 | GJ6: =IF(ISERROR(GA8*GA9),"",GA8*GA9) -> 31110.398 | GK6: =IF(ISERROR(GB8*GB9),"",GB8*GB9) -> 17563.463 | GL6: =IF(ISERROR(GC8*GC9),"",GC8*GC9) -> 6311.1234 | GM6: =IF(ISERROR(GD8*GD9),"",GD8*GD9) -> 1726.3344 | GN6: =IF(ISERROR(GE8*GE9),"",GE8*GE9) -> 401.319 | GO6: =IF(ISERROR(GF8*GF9),"",GF8*GF9) -> 6077.1336 | GP6: =IF(ISERROR(GG8*GG9),"",GG8*GG9) -> 17795.953 | GQ6: =IF(ISERROR(GH8*GH9),"",GH8*GH9) -> 37689.567 | GR6: =IF(GJ6<>"",SUM(GJ6:GQ6),"") -> 118675.29 | GS6: =IF(GM10<>"",(GS5-GM10)/GM9,"") -> -1.3984003 | GT6: =IF(GS6="","",IF(GS6>0,GW7+GS6,-1)) -> -1 | GU6: =IF(GS6="","",IF(GS6>0,GY7+GS6,-1)) -> -1 | GV6: =IF(GS6="","",IF(GS6>0,GT6,-1)) -> -1 | GW6: =IF(GS6="","",IF(GS6>0,GU6,-1)) -> -1 | GX6: =IF(GS6="","",IF(GS6>0,GW7,-1)) -> -1 | GY6: =IF(GS6="","",IF(GS6>0,GT6,-1)) -> -1 | GZ6: =IF(GS6="","",IF(GS6>0,GV6,-1)) -> -1 | HA6: =IF(GS6="","",IF(GS6>0,GV6,-1)) -> -1 | HB6: =IF(ISNUMBER(AD10),AD10*$W9,"") | HC6: =IF(ISNUMBER(AE10),AE10*$W9,"") | HD6: =IF(ISNUMBER(AF10),AF10*$W9,"") | HE6: =IF(ISNUMBER(AG10),AG10*$W9,"") | HF6: =IF(ISNUMBER(AH10),AH10*$W9,"") | HG6: =IF(ISNUMBER(AI10),AI10*$W9,"") | HH6: =IF(ISNUMBER(AJ10),AJ10*$W9,"") | HI6: =IF(ISNUMBER(AK10),AK10*$W9,"") | HJ6: =IF(HB6<>"",AVERAGE(HB6:HI6),"") | HK6: =IF(ISERROR(HB8*HB9),"",HB8*HB9) | HL6: =IF(ISERROR(HC8*HC9),"",HC8*HC9) | HM6: =IF(ISERROR(HD8*HD9),"",HD8*HD9) | HN6: =IF(ISERROR(HE8*HE9),"",HE8*HE9) | HO6: =IF(ISERROR(HF8*HF9),"",HF8*HF9) | HP6: =IF(ISERROR(HG8*HG9),"",HG8*HG9) | HQ6: =IF(ISERROR(HH8*HH9),"",HH8*HH9) | HR6: =IF(ISERROR(HI8*HI9),"",HI8*HI9) | HS6: =IF(HK6<>"",SUM(HK6:HR6),"") | HT6: =IF(HN10<>"",(HT5-HN10)/HN9,"") | HU6: =IF(HT6="","",IF(HT6>0,HX7+HT6,-1)) | HV6: =IF(HT6="","",IF(HT6>0,HZ7+HT6,-1)) | HW6: =IF(HT6="","",IF(HT6>0,HU6,-1)) | HX6: =IF(HT6="","",IF(HT6>0,HV6,-1)) | HY6: =IF(HT6="","",IF(HT6>0,HX7,-1)) | HZ6: =IF(HT6="","",IF(HT6>0,HU6,-1)) | IA6: =IF(HT6="","",IF(HT6>0,HW6,-1)) | IB6: =IF(HT6="","",IF(HT6>0,HW6,-1)) | IC6: =IF(ISNUMBER(AD11),AD11*$W9,"") | ID6: =IF(ISNUMBER(AE11),AE11*$W9,"") | IE6: =IF(ISNUMBER(AF11),AF11*$W9,"") | IF6: =IF(ISNUMBER(AG11),AG11*$W9,"") | IG6: =IF(ISNUMBER(AH11),AH11*$W9,"") | IH6: =IF(ISNUMBER(AI11),AI11*$W9,"") | II6: =IF(ISNUMBER(AJ11),AJ11*$W9,"") | IJ6: =IF(ISNUMBER(AK11),AK11*$W9,"") | IK6: =IF(IC6<>"",AVERAGE(IC6:IJ6),"") | IL6: =IF(ISERROR(IC8*IC9),"",IC8*IC9) | IM6: =IF(ISERROR(ID8*ID9),"",ID8*ID9) | IN6: =IF(ISERROR(IE8*IE9),"",IE8*IE9) | IO6: =IF(ISERROR(IF8*IF9),"",IF8*IF9) | IP6: =IF(ISERROR(IG8*IG9),"",IG8*IG9) | IQ6: =IF(ISERROR(IH8*IH9),"",IH8*IH9) | IR6: =IF(ISERROR(II8*II9),"",II8*II9) | IS6: =IF(ISERROR(IJ8*IJ9),"",IJ8*IJ9) | IT6: =IF(IL6<>"",SUM(IL6:IS6),"") | IU6: =IF(IO10<>"",(IU5-IO10)/IO9,"") | IV6: =IF(IU6="","",IF(IU6>0,IY7+IU6,-1)) | IW6: =IF(IU6="","",IF(IU6>0,JA7+IU6,-1)) | IX6: =IF(IU6="","",IF(IU6>0,IV6,-1)) | IY6: =IF(IU6="","",IF(IU6>0,IW6,-1)) | IZ6: =IF(IU6="","",IF(IU6>0,IY7,-1)) | JA6: =IF(IU6="","",IF(IU6>0,IV6,-1)) | JB6: =IF(IU6="","",IF(IU6>0,IX6,-1)) | JC6: =IF(IU6="","",IF(IU6>0,IX6,-1)) | JD6: =IF(T7<>"",T7,"") -> 2 | JE6: =IF(JD5<>"",MAX(DV11,DX11),"") | JF6: =IF(JD6<>"",MAX(EW11,EY11),"") -> 15027.167 | JG6: =IF(JD7<>"",MAX(FX11,FZ11),"") -> 20146.311 | JH6: =IF(JD8<>"",MAX(GY11,HA11),"") -> 16567.629 | JI6: =IF(JD9<>"",MAX(HZ11,IB11),"") | JJ6: =IF(JJ5<>"",MAX(JA11,JC11),"") | JK6: =AVERAGE(JE6:JJ6) -> 17247.036 | JL6: =IF(ISNUMBER(JE10),JE10^2,"") | JM6: =IF(ISNUMBER(JF10),JF10^2,"") -> 2.4020313e-06 | JN6: =IF(ISNUMBER(JG10),JG10^2,"") -> 2.3324304e-08 | JO6: =IF(ISNUMBER(JH10),JH10^2,"") -> 2.8987507e-06 | JP6: =IF(ISNUMBER(JI10),JI10^2,"") | JQ6: =IF(ISNUMBER(JJ10),JJ10^2,"") | JR6: =SUM(JL6:JQ6) -> 5.3241063e-06 | JS6: y= | JT6: =JM11*JT5^2+JO11*JT5+JQ11 -> 20180.415 | JU6: =IF(T7<>0,LOOKUP(T7,Tara!$G$6:$G$185,Tara!$J$6:$J$185)/10,"") -> 11.494 | JV6: =IF(ISNUMBER(U7),MAX(Z7:AC7)-MIN(Z7:AC7),"") -> 0.16 | JW6: =IF(JV6<>"",JV6/JU6/10,"") -> 0.0013920306 | JX6: =IF(JD5<>"",JW5*100,"") | JY6: =IF(JD6<>"",JW6*100,"") -> 0.13920306 | JZ6: =IF(JD7<>"",JW7*100,"") -> 0.052173913 | KA6: =IF(JD8<>"",JW8*100,"") -> 0.043557801 | KB6: =IF(JD9<>"",JW9*100,"") | KC6: =IF(KC5<>"",JW10*100,"") | KD6: =AVERAGE(JX6:KC6) -> 0.078311592 | KE6: =IF(ISNUMBER(JX10),JX10^2,"") | KF6: =IF(ISNUMBER(JY10),JY10^2,"") -> 2.4020313e-06 | KG6: =IF(ISNUMBER(JZ10),JZ10^2,"") -> 2.3324304e-08 | KH6: =IF(ISNUMBER(KA10),KA10^2,"") -> 2.8987507e-06 | KI6: =IF(ISNUMBER(KB10),KB10^2,"") | KJ6: =IF(ISNUMBER(KC10),KC10^2,"") | KK6: =SUM(KE6:KJ6) -> 5.3241063e-06 | KL6: y= | KM6: =KF11*KM5^2+KH11*KM5+KJ11 -> 0.037590853 | KN6: =IF(ISNUMBER(AN5),LOOKUP(AN5,Tara!$A$6:$A$185,Tara!$B$6:$B$185),"") | KO6: =IF(ISNUMBER(AO5),LOOKUP(AO5,Tara!$A$6:$A$185,Tara!$B$6:$B$185),"") | KP6: =IF(ISNUMBER(AP5),LOOKUP(AP5,Tara!$A$6:$A$185,Tara!$B$6:$B$185),"") | KQ6: =IF(ISNUMBER(AQ5),LOOKUP(AQ5,Tara!$A$6:$A$185,Tara!$B$6:$B$185),"") | KR6: =IF(ISNUMBER(AR5),LOOKUP(AR5,Tara!$A$6:$A$185,Tara!$B$6:$B$185),"") | KS6: =IF(ISNUMBER(AN9),LOOKUP(AN9,Tara!$E$6:$E$185,Tara!$F$6:$F$185),"") | KT6: =IF(ISNUMBER(AO9),LOOKUP(AO9,Tara!$E$6:$E$185,Tara!$F$6:$F$185),"") | KU6: =IF(ISNUMBER(AP9),LOOKUP(AP9,Tara!$E$6:$E$185,Tara!$F$6:$F$185),"") | KV6: =IF(ISNUMBER(AQ9),LOOKUP(AQ9,Tara!$E$6:$E$185,Tara!$F$6:$F$185),"") | KW6: =IF(ISNUMBER(AR9),LOOKUP(AR9,Tara!$E$6:$E$185,Tara!$F$6:$F$185),"") | KY6: =IF(AX10<>"",AX10,"") | KZ6: =IF(BA10<>"",BA10,"") | LA6: =IF(ISNUMBER(AT9),LOOKUP(AT9,Tara!$C$6:$C$185,Tara!$D$6:$D$185),"") -> 26.16 | LB6: =IF(ISNUMBER(AW9),LOOKUP(AW9,Tara!$C$6:$C$185,Tara!$D$6:$D$185),"") -> 34.16 | LC6: =IF(BG9<>"",BG9,"") -> 2501.74 | LD6: =IF(BH9<>"",BH9,"") -> 153.66 | LE6: =IF(AZ9<>"",AZ9,"") -> 0 | LF6: =IF(BA9<>"",BA9,"") -> 0 | LG6: =IF(BB9<>"",BB9,"") -> 56.94 | LH6: =IF(BC9<>"",BC9,"") -> 90.69 | LI6: =IF(BD9<>"",BD9,"") -> 315.09 | LJ6: =IF(BE9<>"",BE9,"") -> 402.2 | LK6: =IF(BF9<>"",BF9,"") -> 311.08 | LL6: =IF(BI9<>"",BI9,"") -> 32.71 | LM6: =IF(BK9<>"",BK9,"") -> 54.51 | LN6: =IF(LM9="","",IF(AND(LE9>=93%,LE9<=100%,LI9>=23%,LI9<=72%,LJ9>20%,LJ9<=60%,LK9>=10%,LK9<=45%,LL9>=6%,LL9<=22%,LM9>=0%,LM9<=10%),"Faixa A")) -> FALSE | LO6: =IF(LM9="","",IF(AND(LG9>=93%,LG9<=100%,LJ9>=50%,LJ9<=100%,LK9>=35%,LK9<=100%,LL9>=18%,LL9<=52%,LM9>=4%,LM9<=22%),"Faixa E")) -> FALSE | LR6: FAIXA | MF6: Dados da Amostra | MI6: Granulometria | MS6: Limites Físicos | MZ6: Laboratorio | ND6: Campo | NG6: Ensaioe de ISC/EXP
