Workbook
Name _bri1: #REF!
Name _bri2: #REF!
Name _drb1: #REF!
Name _drb2: #REF!
Name _j100000: #REF!
Name _Rbv1: '[2]Página 16'!$C$3:$C$7
Name A_impresión_IM: #N/A
Name amostra: #REF!
Name arei: #REF!
Name BI: [3]Teor!$A$3:$G$7
Name bica: #REF!
Name btt: #REF!
Name button_area_1: #REF!
Name CAN: #N/A
Name cbr: #REF!
Name celltips_area: #REF!
Name cinco: #REF!
Name Cod: INDIRECT('[4]FR-FP-01 Solicitação de Placas'!$C$11)
Name Cod_1: INDIRECT('[4]FR-FP-01 Solicitação de Placas'!$G$11)
Name Cod_10: INDIRECT('[4]FR-FP-01 Solicitação de Placas'!$G$47)
Name Cod_11: INDIRECT('[4]FR-FP-01 Solicitação de Placas'!$K$47)
Name Cod_12: INDIRECT('[4]FR-FP-01 Solicitação de Placas'!$C$59)
Name Cod_13: INDIRECT('[4]FR-FP-01 Solicitação de Placas'!$G$59)
Name Cod_14: INDIRECT('[4]FR-FP-01 Solicitação de Placas'!$K$59)
Name Cod_15: INDIRECT('[4]FR-FP-01 Solicitação de Placas'!$C$71)
Name Cod_16: INDIRECT('[4]FR-FP-01 Solicitação de Placas'!$G$71)
Name Cod_17: INDIRECT('[4]FR-FP-01 Solicitação de Placas'!$K$71)
Name Cod_18: INDIRECT('[4]FR-FP-01 Solicitação de Placas'!$C$83)
Name Cod_19: INDIRECT('[4]FR-FP-01 Solicitação de Placas'!$G$83)
Name Cod_2: INDIRECT('[4]FR-FP-01 Solicitação de Placas'!$K$11)
Name Cod_20: INDIRECT('[4]FR-FP-01 Solicitação de Placas'!$K$83)
Name Cod_3: INDIRECT('[4]FR-FP-01 Solicitação de Placas'!$C$23)
Name Cod_4: INDIRECT('[4]FR-FP-01 Solicitação de Placas'!$G$23)
Name Cod_5: INDIRECT('[4]FR-FP-01 Solicitação de Placas'!$K$23)
Name Cod_6: INDIRECT('[4]FR-FP-01 Solicitação de Placas'!$C$35)
Name Cod_7: INDIRECT('[4]FR-FP-01 Solicitação de Placas'!$G$35)
Name Cod_8: INDIRECT('[4]FR-FP-01 Solicitação de Placas'!$K$35)
Name Cod_9: INDIRECT('[4]FR-FP-01 Solicitação de Placas'!$C$47)
Name CODIGÓ: #REF!
Name CÓDIGO: #N/A
Name comple: [5]Macro1!$B$1:$B$65536
Name correção: #REF!
Name d: #REF!
Name dez: #REF!
Name dois: #REF!
Name doze: #REF!
Name drar: #REF!
Name drfi: #REF!
Name drpe: #REF!
Name eng: #REF!
Name f: #REF!
Name fill: #REF!
Name gac: #REF!
Name gag: #REF!
Name GAUS: [6]TABLA!$N$10:$P$409
Name h: #REF!
Name IP: [8]resumo!#REF!
Name kp: #REF!
Name lab: #REF!
Name LL: [8]resumo!#REF!

Sheet FR-LAB-51_Rev.01
B3: #VALUE! | D3: SOLOS - DETERMINAÇÃO DO MÓDULO DE RESILIÊNCIA
D4: TIPO: | N4: NÍVEL:
D5: FORMULÁRIO | N5: TÁTICO/OPERACIONAL
D6: 1.1 CÓDIGO | K6: 1.2 EMISSÃO | N6: 1.3 REVISÃO | R6: 1.4 FOLHA Nº / TOTAL DE FOLHAS:
D7: FR-LAB-51 | K7: 45394 | N7: 00 | R7: Página 1 de 2
B9: Nº O.S: | M9: Data do ensaio:
B10: Material: | M10: Registro da amostra:
B11: Procedência material:
B12: Informações complementar:
B13: Documentos de Referência
B14: DNIT 134 - ME - Pavimentação - Determinação do módulo de resiliência
B15: Dados Específicos do Corpo de Prova
B16: Data de compactação: | M16: Energia de compactação:
B17: Tipo de estabilizante químico: | M17: Tamanho do Corpo de Prova (mm):
B18: Tempo de cura (dias): | M18: Teor de umidade do Corpo de Prova (%):
B19: Porcentagem (em peso) do estabilizante químico (%): | M19: Peso específico seco do Corpo de Prova (kN/m³):
B20: Curso do LVDT empregado (mm): | M20: Grau de compactação do Corpo de Prova (%):
B21: Resumo dos Resultados
B22: Tensão confinante σ3 (MPa) | C22: Tensão desvio σd (MPa) | E22: Deslocamento recuperável δ (mm) | G22: Deformação resiliente ε (%) | I22: Módulo de Resiliência MR (MPa) | K22: Tensão desvio σd (MPa) | M22: Deslocamento recuperável δ (mm) | O22: Deformação resiliente ε (%) | Q22: Módulo de Resiliência MR (MPa) | S22: Tensão desvio σd (MPa) | U22: Deslocamento recuperável δ (mm) | W22: Deformação resiliente ε (%) | Y22: Módulo de Resiliência MR (MPa) | AC22: Módulo de Resiliência (Mpa)
B24: =[12]Relatório!A22 -> 0 | C24: =[12]Relatório!B22 -> 0 | E24: =[12]Relatório!C22 -> 0 | G24: =[12]Relatório!D22 -> 0 | I24: =[12]Relatório!E22 -> 0 | K24: =[12]Relatório!G22 -> 0 | M24: =[12]Relatório!H22 -> 0 | O24: =[12]Relatório!I22 -> 0 | Q24: =[12]Relatório!J22 -> 0 | S24: =[12]Relatório!K22 -> 0 | U24: =[12]Relatório!M22 -> 0 | W24: =[12]Relatório!N22 -> 0 | Y24: =[12]Relatório!O22 -> 0
B25: =[12]Relatório!A23 -> 0 | C25: =[12]Relatório!B23 -> 0 | E25: =[12]Relatório!C23 -> 0 | G25: =[12]Relatório!D23 -> 0 | I25: =[12]Relatório!E23 -> 0 | K25: =[12]Relatório!G23 -> 0 | M25: =[12]Relatório!H23 -> 0 | O25: =[12]Relatório!I23 -> 0 | Q25: =[12]Relatório!J23 -> 0 | S25: =[12]Relatório!K23 -> 0 | U25: =[12]Relatório!M23 -> 0 | W25: =[12]Relatório!N23 -> 0 | Y25: =[12]Relatório!O23 -> 0
B26: =[12]Relatório!A24 -> 0 | C26: =[12]Relatório!B24 -> 0 | E26: =[12]Relatório!C24 -> 0 | G26: =[12]Relatório!D24 -> 0 | I26: =[12]Relatório!E24 -> 0 | K26: =[12]Relatório!G24 -> 0 | M26: =[12]Relatório!H24 -> 0 | O26: =[12]Relatório!I24 -> 0 | Q26: =[12]Relatório!J24 -> 0 | S26: =[12]Relatório!K24 -> 0 | U26: =[12]Relatório!M24 -> 0 | W26: =[12]Relatório!N24 -> 0 | Y26: =[12]Relatório!O24 -> 0
B27: =[12]Relatório!A25 -> 0 | C27: =[12]Relatório!B25 -> 0 | E27: =[12]Relatório!C25 -> 0 | G27: =[12]Relatório!D25 -> 0 | I27: =[12]Relatório!E25 -> 0 | K27: =[12]Relatório!G25 -> 0 | M27: =[12]Relatório!H25 -> 0 | O27: =[12]Relatório!I25 -> 0 | Q27: =[12]Relatório!J25 -> 0 | S27: =[12]Relatório!K25 -> 0 | U27: =[12]Relatório!M25 -> 0 | W27: =[12]Relatório!N25 -> 0 | Y27: =[12]Relatório!O25 -> 0
B28: =[12]Relatório!A26 -> 0 | C28: =[12]Relatório!B26 -> 0 | E28: =[12]Relatório!C26 -> 0 | G28: =[12]Relatório!D26 -> 0 | I28: =[12]Relatório!E26 -> 0 | K28: =[12]Relatório!G26 -> 0 | M28: =[12]Relatório!H26 -> 0 | O28: =[12]Relatório!I26 -> 0 | Q28: =[12]Relatório!J26 -> 0 | S28: =[12]Relatório!K26 -> 0 | U28: =[12]Relatório!M26 -> 0 | W28: =[12]Relatório!N26 -> 0 | Y28: =[12]Relatório!O26 -> 0
B29: =[12]Relatório!A27 -> 0 | C29: =[12]Relatório!B27 -> 0 | E29: =[12]Relatório!C27 -> 0 | G29: =[12]Relatório!D27 -> 0 | I29: =[12]Relatório!E27 -> 0 | K29: =[12]Relatório!G27 -> 0 | M29: =[12]Relatório!H27 -> 0 | O29: =[12]Relatório!I27 -> 0 | Q29: =[12]Relatório!J27 -> 0 | S29: =[12]Relatório!K27 -> 0 | U29: =[12]Relatório!M27 -> 0 | W29: =[12]Relatório!N27 -> 0 | Y29: =[12]Relatório!O27 -> 0
B30: =[12]Relatório!A28 -> 0 | C30: =[12]Relatório!B28 -> 0 | E30: =[12]Relatório!C28 -> 0 | G30: =[12]Relatório!D28 -> 0 | I30: =[12]Relatório!E28 -> 0 | K30: =[12]Relatório!G28 -> 0 | M30: =[12]Relatório!H28 -> 0 | O30: =[12]Relatório!I28 -> 0 | Q30: =[12]Relatório!J28 -> 0 | S30: =[12]Relatório!K28 -> 0 | U30: =[12]Relatório!M28 -> 0 | W30: =[12]Relatório!N28 -> 0 | Y30: =[12]Relatório!O28 -> 0
B31: =[12]Relatório!A29 -> 0 | C31: =[12]Relatório!B29 -> 0 | E31: =[12]Relatório!C29 -> 0 | G31: =[12]Relatório!D29 -> 0 | I31: =[12]Relatório!E29 -> 0 | K31: =[12]Relatório!G29 -> 0 | M31: =[12]Relatório!H29 -> 0 | O31: =[12]Relatório!I29 -> 0 | Q31: =[12]Relatório!J29 -> 0 | S31: =[12]Relatório!K29 -> 0 | U31: =[12]Relatório!M29 -> 0 | W31: =[12]Relatório!N29 -> 0 | Y31: =[12]Relatório!O29 -> 0
B32: =[12]Relatório!A30 -> 0 | C32: =[12]Relatório!B30 -> 0 | E32: =[12]Relatório!C30 -> 0 | G32: =[12]Relatório!D30 -> 0 | I32: =[12]Relatório!E30 -> 0 | K32: =[12]Relatório!G30 -> 0 | M32: =[12]Relatório!H30 -> 0 | O32: =[12]Relatório!I30 -> 0 | Q32: =[12]Relatório!J30 -> 0 | S32: =[12]Relatório!K30 -> 0 | U32: =[12]Relatório!M30 -> 0 | W32: =[12]Relatório!N30 -> 0 | Y32: =[12]Relatório!O30 -> 0
B33: =[12]Relatório!A31 -> 0 | C33: =[12]Relatório!B31 -> 0 | E33: =[12]Relatório!C31 -> 0 | G33: =[12]Relatório!D31 -> 0 | I33: =[12]Relatório!E31 -> 0 | K33: =[12]Relatório!G31 -> 0 | M33: =[12]Relatório!H31 -> 0 | O33: =[12]Relatório!I31 -> 0 | Q33: =[12]Relatório!J31 -> 0 | S33: =[12]Relatório!K31 -> 0 | U33: =[12]Relatório!M31 -> 0 | W33: =[12]Relatório!N31 -> 0 | Y33: =[12]Relatório!O31 -> 0
B34: =[12]Relatório!A32 -> 0 | C34: =[12]Relatório!B32 -> 0 | E34: =[12]Relatório!C32 -> 0 | G34: =[12]Relatório!D32 -> 0 | I34: =[12]Relatório!E32 -> 0 | K34: =[12]Relatório!G32 -> 0 | M34: =[12]Relatório!H32 -> 0 | O34: =[12]Relatório!I32 -> 0 | Q34: =[12]Relatório!J32 -> 0 | S34: =[12]Relatório!K32 -> 0 | U34: =[12]Relatório!M32 -> 0 | W34: =[12]Relatório!N32 -> 0 | Y34: =[12]Relatório!O32 -> 0
B35: =[12]Relatório!A33 -> 0 | C35: =[12]Relatório!B33 -> 0 | E35: =[12]Relatório!C33 -> 0 | G35: =[12]Relatório!D33 -> 0 | I35: =[12]Relatório!E33 -> 0 | K35: =[12]Relatório!G33 -> 0 | M35: =[12]Relatório!H33 -> 0 | O35: =[12]Relatório!I33 -> 0 | Q35: =[12]Relatório!J33 -> 0 | S35: =[12]Relatório!K33 -> 0 | U35: =[12]Relatório!M33 -> 0 | W35: =[12]Relatório!N33 -> 0 | Y35: =[12]Relatório!O33 -> 0
... B41: =[12]Relatório!A39 -> 0 | C41: =[12]Relatório!B39 -> 0 | E41: =[12]Relatório!C39 -> 0 | G41: =[12]Relatório!D39 -> 0 | I41: =[12]Relatório!E39 -> 0 | K41: =[12]Relatório!G39 -> 0 | M41: =[12]Relatório!H39 -> 0 | O41: =[12]Relatório!I39 -> 0 | Q41: =[12]Relatório!J39 -> 0 | S41: =[12]Relatório!K39 -> 0 | U41: =[12]Relatório!M39 -> 0 | W41: =[12]Relatório!N39 -> 0 | Y41: =[12]Relatório!O39 -> 0
B42: MODELO COMBINADO
C54: K1 = | K54: K1 = | S54: K1 =
C55: K2 = | K55: K2 = | S55: K2 =
C56: K3 = | K56: K3 = | S56: K3 =
C57: R2 = | K57: R2 = | S57: R2 =
B59: Assinaturas:
B60: ____________________________________________________ | M60: __________________________________________________________
B61: Responsável executor: | M61: Responsável calculista:
...

Sheet GRAFICOS  (3)
G2: CONCRETO ASFÁLTICO - DETERMINAÇÃO DA DENSIDADE APARENTE E GRAU DE COMPACTAÇÃO
G3: TIPO: | N3: NÍVEL:
G4: FORMULÁRIO | N4: TÁTICO/OPERACIONAL
G5: 1.1 CÓDIGO | K5: 1.2 EMISSÃO | N5: 1.3 REVISÃO | R5: 1.4 FOLHA Nº / TOTAL DE FOLHAS:
G6: FR-LAB-51 | K6: 45075 | N6: 00 | R6: Página 2 de 2
B8: Nº O.S: | M8: Data do ensaio:
B9: Material: | M9: Registro da amostra:
B10: Procedência material:
B11: Informações complementar:
B12: Documentos de Referência
B13: DNIT 134 - ME - Pavimentação - Determinação do módulo de resiliência
B14: Resumo dos Resultados
B15: MODELO DEPENDENTE DA TENSÃO CONFINANTE
AC22: Módulo de Resiliência (Mpa)
B25: K1 = | J25: K1 = | S25: K1 =
B26: K2 = | J26: K2 = | S26: K2 =
B27: R2 = | J27: R2 = | S27: R2 =
B28: MODELO DEPENDENTE DA TENSÃO DE DESVIO
B39: K1 = | J39: K1 = | S39: K1 =
B40: K2 = | J40: K2 = | S40: K2 =
B41: R2 = | J41: R2 = | S41: R2 =
B42: MODELO DEPENDENTE DO SOMATÓRIO DAS TENSÕES
B55: K1 = | J55: K1 = | R55: K1 =
B56: K2 = | J56: K2 = | R56: K2 =
B57: R2 = | J57: R2 = | R57: R2 =
B58: Observações
B65: Assinaturas
B66: ____________________________________________________ | M66: __________________________________________________________
B67: Responsável executor: | M67: Responsável calculista:
B69: CICLO DE APROVAÇÃO:
B70: Quedna Reis | J70: Thyago Biasin | P70: Leandro Gomes
B71: ELABORAÇÃO/REVISÃO | J71: ANÁLISE CRÍTICA | P71: APROVAÇÃO
